Workbook

Sheet Inputs
A1: Petra Trauma Centre - inputs (blue = editable). JOD. Tags: see report.
A3: ward_beds | B3: 17
A4: icu_beds | B4: 3
A5: p_ward_day | B5: 120
A6: p_icu_day | B6: 420
A7: p_surgery | B7: 750
A8: p_implant | B8: 220
A9: p_day_surgery | B9: 350
A10: p_day_implant | B10: 30
A11: p_endoscopy | B11: 120
A12: p_er | B12: 45
A13: p_ct | B13: 85
A14: p_opd | B14: 30
... A59: arrangement_fee_pct | B59: 0.005

Sheet Capex
A1: Capital cost (values from model; edit in ptc_model.py or here)
A3: Land (purchase + registration fees) | B3: 0
A4: Building (GFA x cost/m2, incl. expansion provision) | B4: 1680000
A5: Design and supervision | B5: 100800
A6: Specialised MEP systems | B6: 330000
A7: Medical equipment | B7: 1300000
A8: Furniture and IT (HIS/EMR/PACS) | B8: 160000
A9: Ambulances | B9: 70000
A10: Contingency | B10: 331000
A11: Pre-opening costs | B11: 280000
A12: Fixed capex total | B12: =SUM(B3:B11)
A13: Interest during construction | B13: =Debt!B6+Debt!B14
A14: Arrangement fees | B14: =(Inputs!$B$47+Inputs!$B$51)*Inputs!$B$59
A15: Cash reserve | B15: =Inputs!$B$58
A16: TOTAL USES | B16: =SUM(B12:B15)
A17: Debt (T1+T2+T3) | B17: =Inputs!$B$47+Inputs!$B$51+Inputs!$B$55
A18: Owner equity | B18: =B16-B17
A19: Equity share | B19: =B18/B16
A21: Depreciable classes | C21: Life (years)
A22: building | B22: 1948800 | C22: 33
A23: mep | B23: 363000 | C23: 10
A24: equipment | B24: 1430000 | C24: 8
A25: furniture_it | B25: 160000 | C25: 5
A26: vehicles | B26: 70000 | C26: 7
A27: pre_opening | B27: 280000 | C27: 5

Sheet Drivers
A1: Annual drivers (blue = editable)
A2: Year | B2: 2029 | C2: 2030 | D2: 2031 | E2: 2032 | F2: 2033 | G2: 2034 | H2: 2035 | I2: 2036 | J2: 2037 | K2: 2038
A3: ward_occ | B3: 0.38 | C3: 0.5 | D3: 0.6 | E3: 0.66 | F3: 0.7 | G3: 0.72 | H3: 0.72 | I3: 0.72 | J3: 0.72 | K3: 0.72
A4: icu_occ | B4: 0.3 | C4: 0.42 | D4: 0.52 | E4: 0.6 | F4: 0.62 | G4: 0.65 | H4: 0.65 | I4: 0.65 | J4: 0.65 | K4: 0.65
A5: surgeries | B5: 500 | C5: 700 | D5: 850 | E5: 950 | F5: 1000 | G5: 1050 | H5: 1050 | I5: 1080 | J5: 1080 | K5: 1080
A6: day_surgeries | B6: 600 | C6: 1000 | D6: 1400 | E6: 1700 | F6: 1900 | G6: 2000 | H6: 2050 | I6: 2100 | J6: 2100 | K6: 2100
A7: endoscopies | B7: 300 | C7: 500 | D7: 700 | E7: 800 | F7: 900 | G7: 950 | H7: 1000 | I7: 1000 | J7: 1000 | K7: 1000
A8: er_per_day | B8: 25 | C8: 32 | D8: 38 | E8: 42 | F8: 45 | G8: 46 | H8: 48 | I8: 50 | J8: 50 | K8: 50
A9: ct_scans | B9: 2000 | C9: 2700 | D9: 3300 | E9: 3800 | F9: 4100 | G9: 4200 | H9: 4300 | I9: 4400 | J9: 4400 | K9: 4400
A10: opd_visits | B10: 7000 | C10: 11000 | D10: 14000 | E10: 16000 | F10: 17500 | G10: 18000 | H10: 18500 | I10: 19000 | J10: 19000 | K10: 19000
A11: physio | B11: 2500 | C11: 4000 | D11: 5000 | E11: 6000 | F11: 6500 | G11: 7000 | H11: 7000 | I11: 7000 | J11: 7000 | K11: 7000
A12: tourist_cases | B12: 400 | C12: 500 | D12: 600 | E12: 600 | F12: 650 | G12: 650 | H12: 700 | I12: 700 | J12: 700 | K12: 700
A13: staffing_factor | B13: 0.75 | C13: 0.85 | D13: 0.95 | E13: 1 | F13: 1 | G13: 1 | H13: 1 | I13: 1 | J13: 1 | K13: 1
... A16: op_year_index | B16: 0 | C16: 1 | D16: 2 | E16: 3 | F16: 4 | G16: 5 | H16: 6 | I16: 7 | J16: 8 | K16: 9
A18: Full-staff payroll incl. on-costs (2029) | B18: =1096800*(1+Inputs!$B$23)

Sheet PnL
A1: Income statement, JOD (live formulas)
A2: Year | B2: 2029 | C2: 2030 | D2: 2031 | E2: 2032 | F2: 2033 | G2: 2034 | H2: 2035 | I2: 2036 | J2: 2037 | K2: 2038
A3: Ward bed-days revenue | B3: =Inputs!$B$3*365*MIN(Drivers!B$3*Inputs!$B$21,0.95)*Inputs!$B$5*(1+Inputs!$B$18)^Drivers!B$16*Inputs!$B$22 | C3: =Inputs!$B$3*365*MIN(Drivers!C$3*Inputs!$B$21,0.95)*Inputs!$B$5*(1+Inputs!$B$18)^Drivers!C$16*Inputs!$B$22 | D3: =Inputs!$B$3*365*MIN(Drivers!D$3*Inputs!$B$21,0.95)*Inputs!$B$5*(1+Inputs!$B$18)^Drivers!D$16*Inputs!$B$22 | E3: =Inputs!$B$3*365*MIN(Drivers!E$3*Inputs!$B$21,0.95)*Inputs!$B$5*(1+Inputs!$B$18)^Drivers!E$16*Inputs!$B$22 | F3: =Inputs!$B$3*365*MIN(Drivers!F$3*Inputs!$B$21,0.95)*Inputs!$B$5*(1+Inputs!$B$18)^Drivers!F$16*Inputs!$B$22 | G3: =Inputs!$B$3*365*MIN(Drivers!G$3*Inputs!$B$21,0.95)*Inputs!$B$5*(1+Inputs!$B$18)^Drivers!G$16*Inputs!$B$22 | H3: =Inputs!$B$3*365*MIN(Drivers!H$3*Inputs!$B$21,0.95)*Inputs!$B$5*(1+Inputs!$B$18)^Drivers!H$16*Inputs!$B$22 | I3: =Inputs!$B$3*365*MIN(Drivers!I$3*Inputs!$B$21,0.95)*Inputs!$B$5*(1+Inputs!$B$18)^Drivers!I$16*Inputs!$B$22 | ... K3: =Inputs!$B$3*365*MIN(Drivers!K$3*Inputs!$B$21,0.95)*Inputs!$B$5*(1+Inputs!$B$18)^Drivers!K$16*Inputs!$B$22
A4: ICU days revenue | B4: =Inputs!$B$4*365*MIN(Drivers!B$4*Inputs!$B$21,0.95)*Inputs!$B$6*(1+Inputs!$B$18)^Drivers!B$16*Inputs!$B$22 | C4: =Inputs!$B$4*365*MIN(Drivers!C$4*Inputs!$B$21,0.95)*Inputs!$B$6*(1+Inputs!$B$18)^Drivers!C$16*Inputs!$B$22 | D4: =Inputs!$B$4*365*MIN(Drivers!D$4*Inputs!$B$21,0.95)*Inputs!$B$6*(1+Inputs!$B$18)^Drivers!D$16*Inputs!$B$22 | E4: =Inputs!$B$4*365*MIN(Drivers!E$4*Inputs!$B$21,0.95)*Inputs!$B$6*(1+Inputs!$B$18)^Drivers!E$16*Inputs!$B$22 | F4: =Inputs!$B$4*365*MIN(Drivers!F$4*Inputs!$B$21,0.95)*Inputs!$B$6*(1+Inputs!$B$18)^Drivers!F$16*Inputs!$B$22 | G4: =Inputs!$B$4*365*MIN(Drivers!G$4*Inputs!$B$21,0.95)*Inputs!$B$6*(1+Inputs!$B$18)^Drivers!G$16*Inputs!$B$22 | H4: =Inputs!$B$4*365*MIN(Drivers!H$4*Inputs!$B$21,0.95)*Inputs!$B$6*(1+Inputs!$B$18)^Drivers!H$16*Inputs!$B$22 | I4: =Inputs!$B$4*365*MIN(Drivers!I$4*Inputs!$B$21,0.95)*Inputs!$B$6*(1+Inputs!$B$18)^Drivers!I$16*Inputs!$B$22 | ... K4: =Inputs!$B$4*365*MIN(Drivers!K$4*Inputs!$B$21,0.95)*Inputs!$B$6*(1+Inputs!$B$18)^Drivers!K$16*Inputs!$B$22
A5: Surgery (hospital fee) | B5: =Drivers!B$5*Inputs!$B$21*Inputs!$B$7*(1+Inputs!$B$18)^Drivers!B$16*Inputs!$B$22 | C5: =Drivers!C$5*Inputs!$B$21*Inputs!$B$7*(1+Inputs!$B$18)^Drivers!C$16*Inputs!$B$22 | D5: =Drivers!D$5*Inputs!$B$21*Inputs!$B$7*(1+Inputs!$B$18)^Drivers!D$16*Inputs!$B$22 | E5: =Drivers!E$5*Inputs!$B$21*Inputs!$B$7*(1+Inputs!$B$18)^Drivers!E$16*Inputs!$B$22 | F5: =Drivers!F$5*Inputs!$B$21*Inputs!$B$7*(1+Inputs!$B$18)^Drivers!F$16*Inputs!$B$22 | G5: =Drivers!G$5*Inputs!$B$21*Inputs!$B$7*(1+Inputs!$B$18)^Drivers!G$16*Inputs!$B$22 | H5: =Drivers!H$5*Inputs!$B$21*Inputs!$B$7*(1+Inputs!$B$18)^Drivers!H$16*Inputs!$B$22 | I5: =Drivers!I$5*Inputs!$B$21*Inputs!$B$7*(1+Inputs!$B$18)^Drivers!I$16*Inputs!$B$22 | ... K5: =Drivers!K$5*Inputs!$B$21*Inputs!$B$7*(1+Inputs!$B$18)^Drivers!K$16*Inputs!$B$22
A6: Day surgery | B6: =Drivers!B$6*Inputs!$B$21*Inputs!$B$9*(1+Inputs!$B$18)^Drivers!B$16*Inputs!$B$22 | C6: =Drivers!C$6*Inputs!$B$21*Inputs!$B$9*(1+Inputs!$B$18)^Drivers!C$16*Inputs!$B$22 | D6: =Drivers!D$6*Inputs!$B$21*Inputs!$B$9*(1+Inputs!$B$18)^Drivers!D$16*Inputs!$B$22 | E6: =Drivers!E$6*Inputs!$B$21*Inputs!$B$9*(1+Inputs!$B$18)^Drivers!E$16*Inputs!$B$22 | F6: =Drivers!F$6*Inputs!$B$21*Inputs!$B$9*(1+Inputs!$B$18)^Drivers!F$16*Inputs!$B$22 | G6: =Drivers!G$6*Inputs!$B$21*Inputs!$B$9*(1+Inputs!$B$18)^Drivers!G$16*Inputs!$B$22 | H6: =Drivers!H$6*Inputs!$B$21*Inputs!$B$9*(1+Inputs!$B$18)^Drivers!H$16*Inputs!$B$22 | I6: =Drivers!I$6*Inputs!$B$21*Inputs!$B$9*(1+Inputs!$B$18)^Drivers!I$16*Inputs!$B$22 | ... K6: =Drivers!K$6*Inputs!$B$21*Inputs!$B$9*(1+Inputs!$B$18)^Drivers!K$16*Inputs!$B$22
A7: Endoscopy | B7: =Drivers!B$7*Inputs!$B$21*Inputs!$B$11*(1+Inputs!$B$18)^Drivers!B$16*Inputs!$B$22 | C7: =Drivers!C$7*Inputs!$B$21*Inputs!$B$11*(1+Inputs!$B$18)^Drivers!C$16*Inputs!$B$22 | D7: =Drivers!D$7*Inputs!$B$21*Inputs!$B$11*(1+Inputs!$B$18)^Drivers!D$16*Inputs!$B$22 | E7: =Drivers!E$7*Inputs!$B$21*Inputs!$B$11*(1+Inputs!$B$18)^Drivers!E$16*Inputs!$B$22 | F7: =Drivers!F$7*Inputs!$B$21*Inputs!$B$11*(1+Inputs!$B$18)^Drivers!F$16*Inputs!$B$22 | G7: =Drivers!G$7*Inputs!$B$21*Inputs!$B$11*(1+Inputs!$B$18)^Drivers!G$16*Inputs!$B$22 | H7: =Drivers!H$7*Inputs!$B$21*Inputs!$B$11*(1+Inputs!$B$18)^Drivers!H$16*Inputs!$B$22 | I7: =Drivers!I$7*Inputs!$B$21*Inputs!$B$11*(1+Inputs!$B$18)^Drivers!I$16*Inputs!$B$22 | ... K7: =Drivers!K$7*Inputs!$B$21*Inputs!$B$11*(1+Inputs!$B$18)^Drivers!K$16*Inputs!$B$22
A8: Implants | B8: =(Drivers!B$5*Inputs!$B$8+Drivers!B$6*Inputs!$B$10)*Inputs!$B$21*(1+Inputs!$B$18)^Drivers!B$16*Inputs!$B$22 | C8: =(Drivers!C$5*Inputs!$B$8+Drivers!C$6*Inputs!$B$10)*Inputs!$B$21*(1+Inputs!$B$18)^Drivers!C$16*Inputs!$B$22 | D8: =(Drivers!D$5*Inputs!$B$8+Drivers!D$6*Inputs!$B$10)*Inputs!$B$21*(1+Inputs!$B$18)^Drivers!D$16*Inputs!$B$22 | E8: =(Drivers!E$5*Inputs!$B$8+Drivers!E$6*Inputs!$B$10)*Inputs!$B$21*(1+Inputs!$B$18)^Drivers!E$16*Inputs!$B$22 | F8: =(Drivers!F$5*Inputs!$B$8+Drivers!F$6*Inputs!$B$10)*Inputs!$B$21*(1+Inputs!$B$18)^Drivers!F$16*Inputs!$B$22 | G8: =(Drivers!G$5*Inputs!$B$8+Drivers!G$6*Inputs!$B$10)*Inputs!$B$21*(1+Inputs!$B$18)^Drivers!G$16*Inputs!$B$22 | H8: =(Drivers!H$5*Inputs!$B$8+Drivers!H$6*Inputs!$B$10)*Inputs!$B$21*(1+Inputs!$B$18)^Drivers!H$16*Inputs!$B$22 | I8: =(Drivers!I$5*Inputs!$B$8+Drivers!I$6*Inputs!$B$10)*Inputs!$B$21*(1+Inputs!$B$18)^Drivers!I$16*Inputs!$B$22 | ... K8: =(Drivers!K$5*Inputs!$B$8+Drivers!K$6*Inputs!$B$10)*Inputs!$B$21*(1+Inputs!$B$18)^Drivers!K$16*Inputs!$B$22
A9: Emergency visits | B9: =Drivers!B$8*365*Inputs!$B$21*Inputs!$B$12*(1+Inputs!$B$18)^Drivers!B$16*Inputs!$B$22 | C9: =Drivers!C$8*365*Inputs!$B$21*Inputs!$B$12*(1+Inputs!$B$18)^Drivers!C$16*Inputs!$B$22 | D9: =Drivers!D$8*365*Inputs!$B$21*Inputs!$B$12*(1+Inputs!$B$18)^Drivers!D$16*Inputs!$B$22 | E9: =Drivers!E$8*365*Inputs!$B$21*Inputs!$B$12*(1+Inputs!$B$18)^Drivers!E$16*Inputs!$B$22 | F9: =Drivers!F$8*365*Inputs!$B$21*Inputs!$B$12*(1+Inputs!$B$18)^Drivers!F$16*Inputs!$B$22 | G9: =Drivers!G$8*365*Inputs!$B$21*Inputs!$B$12*(1+Inputs!$B$18)^Drivers!G$16*Inputs!$B$22 | H9: =Drivers!H$8*365*Inputs!$B$21*Inputs!$B$12*(1+Inputs!$B$18)^Drivers!H$16*Inputs!$B$22 | I9: =Drivers!I$8*365*Inputs!$B$21*Inputs!$B$12*(1+Inputs!$B$18)^Drivers!I$16*Inputs!$B$22 | ... K9: =Drivers!K$8*365*Inputs!$B$21*Inputs!$B$12*(1+Inputs!$B$18)^Drivers!K$16*Inputs!$B$22
A10: CT scans | B10: =Drivers!B$9*Inputs!$B$21*Inputs!$B$13*(1+Inputs!$B$18)^Drivers!B$16*Inputs!$B$22 | C10: =Drivers!C$9*Inputs!$B$21*Inputs!$B$13*(1+Inputs!$B$18)^Drivers!C$16*Inputs!$B$22 | D10: =Drivers!D$9*Inputs!$B$21*Inputs!$B$13*(1+Inputs!$B$18)^Drivers!D$16*Inputs!$B$22 | E10: =Drivers!E$9*Inputs!$B$21*Inputs!$B$13*(1+Inputs!$B$18)^Drivers!E$16*Inputs!$B$22 | F10: =Drivers!F$9*Inputs!$B$21*Inputs!$B$13*(1+Inputs!$B$18)^Drivers!F$16*Inputs!$B$22 | G10: =Drivers!G$9*Inputs!$B$21*Inputs!$B$13*(1+Inputs!$B$18)^Drivers!G$16*Inputs!$B$22 | H10: =Drivers!H$9*Inputs!$B$21*Inputs!$B$13*(1+Inputs!$B$18)^Drivers!H$16*Inputs!$B$22 | I10: =Drivers!I$9*Inputs!$B$21*Inputs!$B$13*(1+Inputs!$B$18)^Drivers!I$16*Inputs!$B$22 | ... K10: =Drivers!K$9*Inputs!$B$21*Inputs!$B$13*(1+Inputs!$B$18)^Drivers!K$16*Inputs!$B$22
A11: Outpatient clinics | B11: =Drivers!B$10*Inputs!$B$21*Inputs!$B$14*(1+Inputs!$B$18)^Drivers!B$16*Inputs!$B$22 | C11: =Drivers!C$10*Inputs!$B$21*Inputs!$B$14*(1+Inputs!$B$18)^Drivers!C$16*Inputs!$B$22 | D11: =Drivers!D$10*Inputs!$B$21*Inputs!$B$14*(1+Inputs!$B$18)^Drivers!D$16*Inputs!$B$22 | E11: =Drivers!E$10*Inputs!$B$21*Inputs!$B$14*(1+Inputs!$B$18)^Drivers!E$16*Inputs!$B$22 | F11: =Drivers!F$10*Inputs!$B$21*Inputs!$B$14*(1+Inputs!$B$18)^Drivers!F$16*Inputs!$B$22 | G11: =Drivers!G$10*Inputs!$B$21*Inputs!$B$14*(1+Inputs!$B$18)^Drivers!G$16*Inputs!$B$22 | H11: =Drivers!H$10*Inputs!$B$21*Inputs!$B$14*(1+Inputs!$B$18)^Drivers!H$16*Inputs!$B$22 | I11: =Drivers!I$10*Inputs!$B$21*Inputs!$B$14*(1+Inputs!$B$18)^Drivers!I$16*Inputs!$B$22 | ... K11: =Drivers!K$10*Inputs!$B$21*Inputs!$B$14*(1+Inputs!$B$18)^Drivers!K$16*Inputs!$B$22
A12: Physiotherapy | B12: =Drivers!B$11*Inputs!$B$21*Inputs!$B$15*(1+Inputs!$B$18)^Drivers!B$16*Inputs!$B$22 | C12: =Drivers!C$11*Inputs!$B$21*Inputs!$B$15*(1+Inputs!$B$18)^Drivers!C$16*Inputs!$B$22 | D12: =Drivers!D$11*Inputs!$B$21*Inputs!$B$15*(1+Inputs!$B$18)^Drivers!D$16*Inputs!$B$22 | E12: =Drivers!E$11*Inputs!$B$21*Inputs!$B$15*(1+Inputs!$B$18)^Drivers!E$16*Inputs!$B$22 | F12: =Drivers!F$11*Inputs!$B$21*Inputs!$B$15*(1+Inputs!$B$18)^Drivers!F$16*Inputs!$B$22 | G12: =Drivers!G$11*Inputs!$B$21*Inputs!$B$15*(1+Inputs!$B$18)^Drivers!G$16*Inputs!$B$22 | H12: =Drivers!H$11*Inputs!$B$21*Inputs!$B$15*(1+Inputs!$B$18)^Drivers!H$16*Inputs!$B$22 | I12: =Drivers!I$11*Inputs!$B$21*Inputs!$B$15*(1+Inputs!$B$18)^Drivers!I$16*Inputs!$B$22 | ... K12: =Drivers!K$11*Inputs!$B$21*Inputs!$B$15*(1+Inputs!$B$18)^Drivers!K$16*Inputs!$B$22
A13: Tourist cases | B13: =Drivers!B$12*Inputs!$B$16*(1+Inputs!$B$18)^Drivers!B$16*Inputs!$B$22 | C13: =Drivers!C$12*Inputs!$B$16*(1+Inputs!$B$18)^Drivers!C$16*Inputs!$B$22 | D13: =Drivers!D$12*Inputs!$B$16*(1+Inputs!$B$18)^Drivers!D$16*Inputs!$B$22 | E13: =Drivers!E$12*Inputs!$B$16*(1+Inputs!$B$18)^Drivers!E$16*Inputs!$B$22 | F13: =Drivers!F$12*Inputs!$B$16*(1+Inputs!$B$18)^Drivers!F$16*Inputs!$B$22 | G13: =Drivers!G$12*Inputs!$B$16*(1+Inputs!$B$18)^Drivers!G$16*Inputs!$B$22 | H13: =Drivers!H$12*Inputs!$B$16*(1+Inputs!$B$18)^Drivers!H$16*Inputs!$B$22 | I13: =Drivers!I$12*Inputs!$B$16*(1+Inputs!$B$18)^Drivers!I$16*Inputs!$B$22 | ... K13: =Drivers!K$12*Inputs!$B$16*(1+Inputs!$B$18)^Drivers!K$16*Inputs!$B$22
A14: Pharmacy (outpatient) | B14: =Inputs!$B$17*(B9+B11) | C14: =Inputs!$B$17*(C9+C11) | D14: =Inputs!$B$17*(D9+D11) | E14: =Inputs!$B$17*(E9+E11) | F14: =Inputs!$B$17*(F9+F11) | G14: =Inputs!$B$17*(G9+G11) | H14: =Inputs!$B$17*(H9+H11) | I14: =Inputs!$B$17*(I9+I11) | ... K14: =Inputs!$B$17*(K9+K11)
A15: Gross revenue | B15: =SUM(B3:B14) | C15: =SUM(C3:C14) | D15: =SUM(D3:D14) | E15: =SUM(E3:E14) | F15: =SUM(F3:F14) | G15: =SUM(G3:G14) | H15: =SUM(H3:H14) | I15: =SUM(I3:I14) | ... K15: =SUM(K3:K14)
A16: Insurer discounts and denials | B16: =-B15*Inputs!$B$19 | C16: =-C15*Inputs!$B$19 | D16: =-D15*Inputs!$B$19 | E16: =-E15*Inputs!$B$19 | F16: =-F15*Inputs!$B$19 | G16: =-G15*Inputs!$B$19 | H16: =-H15*Inputs!$B$19 | I16: =-I15*Inputs!$B$19 | ... K16: =-K15*Inputs!$B$19
A17: NET REVENUE | B17: =B15+B16 | C17: =C15+C16 | D17: =D15+D16 | E17: =E15+E16 | F17: =F15+F16 | G17: =G15+G16 | H17: =H15+H16 | I17: =I15+I16 | ... K17: =K15+K16
A18: Payroll | B18: =Drivers!$B$18*Drivers!B$13*(1+Inputs!$B$24)^Drivers!B$16 | C18: =Drivers!$B$18*Drivers!C$13*(1+Inputs!$B$24)^Drivers!C$16 | D18: =Drivers!$B$18*Drivers!D$13*(1+Inputs!$B$24)^Drivers!D$16 | E18: =Drivers!$B$18*Drivers!E$13*(1+Inputs!$B$24)^Drivers!E$16 | F18: =Drivers!$B$18*Drivers!F$13*(1+Inputs!$B$24)^Drivers!F$16 | G18: =Drivers!$B$18*Drivers!G$13*(1+Inputs!$B$24)^Drivers!G$16 | H18: =Drivers!$B$18*Drivers!H$13*(1+Inputs!$B$24)^Drivers!H$16 | I18: =Drivers!$B$18*Drivers!I$13*(1+Inputs!$B$24)^Drivers!I$16 | ... K18: =Drivers!$B$18*Drivers!K$13*(1+Inputs!$B$24)^Drivers!K$16
A19: Drugs and consumables | B19: =(B17-B8*(1-Inputs!$B$19))*Inputs!$B$25 | C19: =(C17-C8*(1-Inputs!$B$19))*Inputs!$B$25 | D19: =(D17-D8*(1-Inputs!$B$19))*Inputs!$B$25 | E19: =(E17-E8*(1-Inputs!$B$19))*Inputs!$B$25 | F19: =(F17-F8*(1-Inputs!$B$19))*Inputs!$B$25 | G19: =(G17-G8*(1-Inputs!$B$19))*Inputs!$B$25 | H19: =(H17-H8*(1-Inputs!$B$19))*Inputs!$B$25 | I19: =(I17-I8*(1-Inputs!$B$19))*Inputs!$B$25 | ... K19: =(K17-K8*(1-Inputs!$B$19))*Inputs!$B$25
A20: Implants cost | B20: =B8*Inputs!$B$26 | C20: =C8*Inputs!$B$26 | D20: =D8*Inputs!$B$26 | E20: =E8*Inputs!$B$26 | F20: =F8*Inputs!$B$26 | G20: =G8*Inputs!$B$26 | H20: =H8*Inputs!$B$26 | I20: =I8*Inputs!$B$26 | ... K20: =K8*Inputs!$B$26
A21: Doctor incentives | B21: =(B5+B6+B7+B9)*Inputs!$B$27 | C21: =(C5+C6+C7+C9)*Inputs!$B$27 | D21: =(D5+D6+D7+D9)*Inputs!$B$27 | E21: =(E5+E6+E7+E9)*Inputs!$B$27 | F21: =(F5+F6+F7+F9)*Inputs!$B$27 | G21: =(G5+G6+G7+G9)*Inputs!$B$27 | H21: =(H5+H6+H7+H9)*Inputs!$B$27 | I21: =(I5+I6+I7+I9)*Inputs!$B$27 | ... K21: =(K5+K6+K7+K9)*Inputs!$B$27
A22: Radiology reading | B22: =Drivers!B$9*Inputs!$B$21*Inputs!$B$28*(1+Inputs!$B$37)^Drivers!B$16 | C22: =Drivers!C$9*Inputs!$B$21*Inputs!$B$28*(1+Inputs!$B$37)^Drivers!C$16 | D22: =Drivers!D$9*Inputs!$B$21*Inputs!$B$28*(1+Inputs!$B$37)^Drivers!D$16 | E22: =Drivers!E$9*Inputs!$B$21*Inputs!$B$28*(1+Inputs!$B$37)^Drivers!E$16 | F22: =Drivers!F$9*Inputs!$B$21*Inputs!$B$28*(1+Inputs!$B$37)^Drivers!F$16 | G22: =Drivers!G$9*Inputs!$B$21*Inputs!$B$28*(1+Inputs!$B$37)^Drivers!G$16 | H22: =Drivers!H$9*Inputs!$B$21*Inputs!$B$28*(1+Inputs!$B$37)^Drivers!H$16 | I22: =Drivers!I$9*Inputs!$B$21*Inputs!$B$28*(1+Inputs!$B$37)^Drivers!I$16 | ... K22: =Drivers!K$9*Inputs!$B$21*Inputs!$B$28*(1+Inputs!$B$37)^Drivers!K$16
A23: Utilities | B23: =Inputs!$B$29*(1+Inputs!$B$37)^Drivers!B$16 | C23: =Inputs!$B$29*(1+Inputs!$B$37)^Drivers!C$16 | D23: =Inputs!$B$29*(1+Inputs!$B$37)^Drivers!D$16 | E23: =Inputs!$B$29*(1+Inputs!$B$37)^Drivers!E$16 | F23: =Inputs!$B$29*(1+Inputs!$B$37)^Drivers!F$16 | G23: =Inputs!$B$29*(1+Inputs!$B$37)^Drivers!G$16 | H23: =Inputs!$B$29*(1+Inputs!$B$37)^Drivers!H$16 | I23: =Inputs!$B$29*(1+Inputs!$B$37)^Drivers!I$16 | ... K23: =Inputs!$B$29*(1+Inputs!$B$37)^Drivers!K$16
A24: Outsourced services | B24: =Inputs!$B$30*(1+Inputs!$B$37)^Drivers!B$16 | C24: =Inputs!$B$30*(1+Inputs!$B$37)^Drivers!C$16 | D24: =Inputs!$B$30*(1+Inputs!$B$37)^Drivers!D$16 | E24: =Inputs!$B$30*(1+Inputs!$B$37)^Drivers!E$16 | F24: =Inputs!$B$30*(1+Inputs!$B$37)^Drivers!F$16 | G24: =Inputs!$B$30*(1+Inputs!$B$37)^Drivers!G$16 | H24: =Inputs!$B$30*(1+Inputs!$B$37)^Drivers!H$16 | I24: =Inputs!$B$30*(1+Inputs!$B$37)^Drivers!I$16 | ... K24: =Inputs!$B$30*(1+Inputs!$B$37)^Drivers!K$16
A25: Insurance and malpractice | B25: =Inputs!$B$31*(1+Inputs!$B$37)^Drivers!B$16 | C25: =Inputs!$B$31*(1+Inputs!$B$37)^Drivers!C$16 | D25: =Inputs!$B$31*(1+Inputs!$B$37)^Drivers!D$16 | E25: =Inputs!$B$31*(1+Inputs!$B$37)^Drivers!E$16 | F25: =Inputs!$B$31*(1+Inputs!$B$37)^Drivers!F$16 | G25: =Inputs!$B$31*(1+Inputs!$B$37)^Drivers!G$16 | H25: =Inputs!$B$31*(1+Inputs!$B$37)^Drivers!H$16 | I25: =Inputs!$B$31*(1+Inputs!$B$37)^Drivers!I$16 | ... K25: =Inputs!$B$31*(1+Inputs!$B$37)^Drivers!K$16
A26: Marketing and contracts | B26: =Drivers!B$14*(1+Inputs!$B$37)^Drivers!B$16 | C26: =Drivers!C$14*(1+Inputs!$B$37)^Drivers!C$16 | D26: =Drivers!D$14*(1+Inputs!$B$37)^Drivers!D$16 | E26: =Drivers!E$14*(1+Inputs!$B$37)^Drivers!E$16 | F26: =Drivers!F$14*(1+Inputs!$B$37)^Drivers!F$16 | G26: =Drivers!G$14*(1+Inputs!$B$37)^Drivers!G$16 | H26: =Drivers!H$14*(1+Inputs!$B$37)^Drivers!H$16 | I26: =Drivers!I$14*(1+Inputs!$B$37)^Drivers!I$16 | ... K26: =Drivers!K$14*(1+Inputs!$B$37)^Drivers!K$16
A27: IT licences | B27: =Inputs!$B$32*(1+Inputs!$B$37)^Drivers!B$16 | C27: =Inputs!$B$32*(1+Inputs!$B$37)^Drivers!C$16 | D27: =Inputs!$B$32*(1+Inputs!$B$37)^Drivers!D$16 | E27: =Inputs!$B$32*(1+Inputs!$B$37)^Drivers!E$16 | F27: =Inputs!$B$32*(1+Inputs!$B$37)^Drivers!F$16 | G27: =Inputs!$B$32*(1+Inputs!$B$37)^Drivers!G$16 | H27: =Inputs!$B$32*(1+Inputs!$B$37)^Drivers!H$16 | I27: =Inputs!$B$32*(1+Inputs!$B$37)^Drivers!I$16 | ... K27: =Inputs!$B$32*(1+Inputs!$B$37)^Drivers!K$16
A28: General and admin | B28: =(Inputs!$B$33+Inputs!$B$34)*(1+Inputs!$B$37)^Drivers!B$16 | C28: =(Inputs!$B$33+Inputs!$B$34)*(1+Inputs!$B$37)^Drivers!C$16 | D28: =(Inputs!$B$33+Inputs!$B$34)*(1+Inputs!$B$37)^Drivers!D$16 | E28: =(Inputs!$B$33+Inputs!$B$34)*(1+Inputs!$B$37)^Drivers!E$16 | F28: =(Inputs!$B$33+Inputs!$B$34)*(1+Inputs!$B$37)^Drivers!F$16 | G28: =(Inputs!$B$33+Inputs!$B$34)*(1+Inputs!$B$37)^Drivers!G$16 | H28: =(Inputs!$B$33+Inputs!$B$34)*(1+Inputs!$B$37)^Drivers!H$16 | I28: =(Inputs!$B$33+Inputs!$B$34)*(1+Inputs!$B$37)^Drivers!I$16 | ... K28: =(Inputs!$B$33+Inputs!$B$34)*(1+Inputs!$B$37)^Drivers!K$16
A29: Licence fees | B29: =Inputs!$B$35*(1+Inputs!$B$37)^Drivers!B$16 | C29: =Inputs!$B$35*(1+Inputs!$B$37)^Drivers!C$16 | D29: =Inputs!$B$35*(1+Inputs!$B$37)^Drivers!D$16 | E29: =Inputs!$B$35*(1+Inputs!$B$37)^Drivers!E$16 | F29: =Inputs!$B$35*(1+Inputs!$B$37)^Drivers!F$16 | G29: =Inputs!$B$35*(1+Inputs!$B$37)^Drivers!G$16 | H29: =Inputs!$B$35*(1+Inputs!$B$37)^Drivers!H$16 | I29: =Inputs!$B$35*(1+Inputs!$B$37)^Drivers!I$16 | ... K29: =Inputs!$B$35*(1+Inputs!$B$37)^Drivers!K$16
A30: Maintenance | B30: =(Capex!$B$24*Drivers!B$15+Capex!$B$22*Inputs!$B$36)*(1+Inputs!$B$37)^Drivers!B$16 | C30: =(Capex!$B$24*Drivers!C$15+Capex!$B$22*Inputs!$B$36)*(1+Inputs!$B$37)^Drivers!C$16 | D30: =(Capex!$B$24*Drivers!D$15+Capex!$B$22*Inputs!$B$36)*(1+Inputs!$B$37)^Drivers!D$16 | E30: =(Capex!$B$24*Drivers!E$15+Capex!$B$22*Inputs!$B$36)*(1+Inputs!$B$37)^Drivers!E$16 | F30: =(Capex!$B$24*Drivers!F$15+Capex!$B$22*Inputs!$B$36)*(1+Inputs!$B$37)^Drivers!F$16 | G30: =(Capex!$B$24*Drivers!G$15+Capex!$B$22*Inputs!$B$36)*(1+Inputs!$B$37)^Drivers!G$16 | H30: =(Capex!$B$24*Drivers!H$15+Capex!$B$22*Inputs!$B$36)*(1+Inputs!$B$37)^Drivers!H$16 | I30: =(Capex!$B$24*Drivers!I$15+Capex!$B$22*Inputs!$B$36)*(1+Inputs!$B$37)^Drivers!I$16 | ... K30: =(Capex!$B$24*Drivers!K$15+Capex!$B$22*Inputs!$B$36)*(1+Inputs!$B$37)^Drivers!K$16
A31: Bad debts | B31: =B17*Inputs!$B$20 | C31: =C17*Inputs!$B$20 | D31: =D17*Inputs!$B$20 | E31: =E17*Inputs!$B$20 | F31: =F17*Inputs!$B$20 | G31: =G17*Inputs!$B$20 | H31: =H17*Inputs!$B$20 | I31: =I17*Inputs!$B$20 | ... K31: =K17*Inputs!$B$20
A32: TOTAL OPEX | B32: =SUM(B18:B31) | C32: =SUM(C18:C31) | D32: =SUM(D18:D31) | E32: =SUM(E18:E31) | F32: =SUM(F18:F31) | G32: =SUM(G18:G31) | H32: =SUM(H18:H31) | I32: =SUM(I18:I31) | ... K32: =SUM(K18:K31)
A33: EBITDA | B33: =B17-B32 | C33: =C17-C32 | D33: =D17-D32 | E33: =E17-E32 | F33: =F17-F32 | G33: =G17-G32 | H33: =H17-H32 | I33: =I17-I32 | ... K33: =K17-K32
A34: EBITDA margin | B34: =B33/B17 | C34: =C33/C17 | D34: =D33/D17 | E34: =E33/E17 | F34: =F33/F17 | G34: =G33/G17 | H34: =H33/H17 | I34: =I33/I17 | ... K34: =K33/K17
A35: Maintenance capex | B35: =0 | C35: =0 | D35: =D17*Inputs!$B$38 | E35: =E17*Inputs!$B$38 | F35: =F17*Inputs!$B$38 | G35: =G17*Inputs!$B$38 | H35: =H17*Inputs!$B$38 | I35: =I17*Inputs!$B$38 | J35: =J17*Inputs!$B$38 | K35: =K17*Inputs!$B$38
A36: Depreciation and amortisation | B36: =IF(0<Capex!$C$22,Capex!$B$22/Capex!$C$22,0)+IF(0<Capex!$C$23,Capex!$B$23/Capex!$C$23,0)+IF(0<Capex!$C$24,Capex!$B$24/Capex!$C$24,0)+IF(0<Capex!$C$25,Capex!$B$25/Capex!$C$25,0)+IF(0<Capex!$C$26,Capex!$B$26/Capex!$C$26,0)+IF(0<Capex!$C$27,Capex!$B$27/Capex!$C$27,0) | C36: =IF(1<Capex!$C$22,Capex!$B$22/Capex!$C$22,0)+IF(1<Capex!$C$23,Capex!$B$23/Capex!$C$23,0)+IF(1<Capex!$C$24,Capex!$B$24/Capex!$C$24,0)+IF(1<Capex!$C$25,Capex!$B$25/Capex!$C$25,0)+IF(1<Capex!$C$26,Capex!$B$26/Capex!$C$26,0)+IF(1<Capex!$C$27,Capex!$B$27/Capex!$C$27,0)+SUM(B35:B35)/8 | D36: =IF(2<Capex!$C$22,Capex!$B$22/Capex!$C$22,0)+IF(2<Capex!$C$23,Capex!$B$23/Capex!$C$23,0)+IF(2<Capex!$C$24,Capex!$B$24/Capex!$C$24,0)+IF(2<Capex!$C$25,Capex!$B$25/Capex!$C$25,0)+IF(2<Capex!$C$26,Capex!$B$26/Capex!$C$26,0)+IF(2<Capex!$C$27,Capex!$B$27/Capex!$C$27,0)+SUM(B35:C35)/8 | E36: =IF(3<Capex!$C$22,Capex!$B$22/Capex!$C$22,0)+IF(3<Capex!$C$23,Capex!$B$23/Capex!$C$23,0)+IF(3<Capex!$C$24,Capex!$B$24/Capex!$C$24,0)+IF(3<Capex!$C$25,Capex!$B$25/Capex!$C$25,0)+IF(3<Capex!$C$26,Capex!$B$26/Capex!$C$26,0)+IF(3<Capex!$C$27,Capex!$B$27/Capex!$C$27,0)+SUM(B35:D35)/8 | F36: =IF(4<Capex!$C$22,Capex!$B$22/Capex!$C$22,0)+IF(4<Capex!$C$23,Capex!$B$23/Capex!$C$23,0)+IF(4<Capex!$C$24,Capex!$B$24/Capex!$C$24,0)+IF(4<Capex!$C$25,Capex!$B$25/Capex!$C$25,0)+IF(4<Capex!$C$26,Capex!$B$26/Capex!$C$26,0)+IF(4<Capex!$C$27,Capex!$B$27/Capex!$C$27,0)+SUM(B35:E35)/8 | G36: =IF(5<Capex!$C$22,Capex!$B$22/Capex!$C$22,0)+IF(5<Capex!$C$23,Capex!$B$23/Capex!$C$23,0)+IF(5<Capex!$C$24,Capex!$B$24/Capex!$C$24,0)+IF(5<Capex!$C$25,Capex!$B$25/Capex!$C$25,0)+IF(5<Capex!$C$26,Capex!$B$26/Capex!$C$26,0)+IF(5<Capex!$C$27,Capex!$B$27/Capex!$C$27,0)+SUM(B35:F35)/8 | H36: =IF(6<Capex!$C$22,Capex!$B$22/Capex!$C$22,0)+IF(6<Capex!$C$23,Capex!$B$23/Capex!$C$23,0)+IF(6<Capex!$C$24,Capex!$B$24/Capex!$C$24,0)+IF(6<Capex!$C$25,Capex!$B$25/Capex!$C$25,0)+IF(6<Capex!$C$26,Capex!$B$26/Capex!$C$26,0)+IF(6<Capex!$C$27,Capex!$B$27/Capex!$C$27,0)+SUM(B35:G35)/8 | I36: =IF(7<Capex!$C$22,Capex!$B$22/Capex!$C$22,0)+IF(7<Capex!$C$23,Capex!$B$23/Capex!$C$23,0)+IF(7<Capex!$C$24,Capex!$B$24/Capex!$C$24,0)+IF(7<Capex!$C$25,Capex!$B$25/Capex!$C$25,0)+IF(7<Capex!$C$26,Capex!$B$26/Capex!$C$26,0)+IF(7<Capex!$C$27,Capex!$B$27/Capex!$C$27,0)+SUM(B35:H35)/8 | J36: =IF(8<Capex!$C$22,Capex!$B$22/Capex!$C$22,0)+IF(8<Capex!$C$23,Capex!$B$23/Capex!$C$23,0)+IF(8<Capex!$C$24,Capex!$B$24/Capex!$C$24,0)+IF(8<Capex!$C$25,Capex!$B$25/Capex!$C$25,0)+IF(8<Capex!$C$26,Capex!$B$26/Capex!$C$26,0)+IF(8<Capex!$C$27,Capex!$B$27/Capex!$C$27,0)+SUM(B35:I35)/8 | K36: =IF(9<Capex!$C$22,Capex!$B$22/Capex!$C$22,0)+IF(9<Capex!$C$23,Capex!$B$23/Capex!$C$23,0)+IF(9<Capex!$C$24,Capex!$B$24/Capex!$C$24,0)+IF(9<Capex!$C$25,Capex!$B$25/Capex!$C$25,0)+IF(9<Capex!$C$26,Capex!$B$26/Capex!$C$26,0)+IF(9<Capex!$C$27,Capex!$B$27/Capex!$C$27,0)+SUM(C35:J35)/8
A37: Interest | B37: =Debt!C6+Debt!C14+Debt!C22 | C37: =Debt!D6+Debt!D14+Debt!D22 | D37: =Debt!E6+Debt!E14+Debt!E22 | E37: =Debt!F6+Debt!F14+Debt!F22 | F37: =Debt!G6+Debt!G14+Debt!G22 | G37: =Debt!H6+Debt!H14+Debt!H22 | H37: =Debt!I6+Debt!I14+Debt!I22 | I37: =Debt!J6+Debt!J14+Debt!J22 | ... K37: =Debt!L6+Debt!L14+Debt!L22
A38: Profit before tax | B38: =B33-B36-B37 | C38: =C33-C36-C37 | D38: =D33-D36-D37 | E38: =E33-E36-E37 | F38: =F33-F36-F37 | G38: =G33-G36-G37 | H38: =H33-H36-H37 | I38: =I33-I36-I37 | ... K38: =K33-K36-K37
A39: Loss brought forward | B39: =0 | C39: =MIN(B38+B39,0) | D39: =MIN(C38+C39,0) | E39: =MIN(D38+D39,0) | F39: =MIN(E38+E39,0) | G39: =MIN(F38+F39,0) | H39: =MIN(G38+G39,0) | I39: =MIN(H38+H39,0) | J39: =MIN(I38+I39,0) | K39: =MIN(J38+J39,0)
A40: Income tax | B40: =MAX(B38+B39,0)*Inputs!$B$42*IF(Drivers!B$16<Inputs!$B$44,1-Inputs!$B$43,1) | C40: =MAX(C38+C39,0)*Inputs!$B$42*IF(Drivers!C$16<Inputs!$B$44,1-Inputs!$B$43,1) | D40: =MAX(D38+D39,0)*Inputs!$B$42*IF(Drivers!D$16<Inputs!$B$44,1-Inputs!$B$43,1) | E40: =MAX(E38+E39,0)*Inputs!$B$42*IF(Drivers!E$16<Inputs!$B$44,1-Inputs!$B$43,1) | F40: =MAX(F38+F39,0)*Inputs!$B$42*IF(Drivers!F$16<Inputs!$B$44,1-Inputs!$B$43,1) | G40: =MAX(G38+G39,0)*Inputs!$B$42*IF(Drivers!G$16<Inputs!$B$44,1-Inputs!$B$43,1) | H40: =MAX(H38+H39,0)*Inputs!$B$42*IF(Drivers!H$16<Inputs!$B$44,1-Inputs!$B$43,1) | I40: =MAX(I38+I39,0)*Inputs!$B$42*IF(Drivers!I$16<Inputs!$B$44,1-Inputs!$B$43,1) | ... K40: =MAX(K38+K39,0)*Inputs!$B$42*IF(Drivers!K$16<Inputs!$B$44,1-Inputs!$B$43,1)
...

Sheet Debt
A1: Debt schedules (annual; T1/T2 drawn mid-2028, grace from draw year; T3 lease from 2029)
A2: T1 CBJ economic-sectors programme | B2: 2028 | C2: 2029 | D2: 2030 | E2: 2031 | F2: 2032 | G2: 2033 | H2: 2034 | I2: 2035 | J2: 2036 | K2: 2037 | L2: 2038
A3: Opening balance | B3: =0 | C3: =B8 | D3: =C8 | E3: =D8 | F3: =E8 | G3: =F8 | H3: =G8 | I3: =H8 | J3: =I8 | ... L3: =K8
A4: Drawdown | B4: =Inputs!$B$47 | C4: =0 | D4: =0 | E4: =0 | F4: =0 | G4: =0 | H4: =0 | I4: =0 | J4: =0 | ... L4: =0
A5: Installment | B5: =0 | C5: =IF(AND(1>=Inputs!$B$49,1<Inputs!$B$49+Inputs!$B$50),PMT(Inputs!$B$48,Inputs!$B$50,-Inputs!$B$47),0) | D5: =IF(AND(2>=Inputs!$B$49,2<Inputs!$B$49+Inputs!$B$50),PMT(Inputs!$B$48,Inputs!$B$50,-Inputs!$B$47),0) | E5: =IF(AND(3>=Inputs!$B$49,3<Inputs!$B$49+Inputs!$B$50),PMT(Inputs!$B$48,Inputs!$B$50,-Inputs!$B$47),0) | F5: =IF(AND(4>=Inputs!$B$49,4<Inputs!$B$49+Inputs!$B$50),PMT(Inputs!$B$48,Inputs!$B$50,-Inputs!$B$47),0) | G5: =IF(AND(5>=Inputs!$B$49,5<Inputs!$B$49+Inputs!$B$50),PMT(Inputs!$B$48,Inputs!$B$50,-Inputs!$B$47),0) | H5: =IF(AND(6>=Inputs!$B$49,6<Inputs!$B$49+Inputs!$B$50),PMT(Inputs!$B$48,Inputs!$B$50,-Inputs!$B$47),0) | I5: =IF(AND(7>=Inputs!$B$49,7<Inputs!$B$49+Inputs!$B$50),PMT(Inputs!$B$48,Inputs!$B$50,-Inputs!$B$47),0) | J5: =IF(AND(8>=Inputs!$B$49,8<Inputs!$B$49+Inputs!$B$50),PMT(Inputs!$B$48,Inputs!$B$50,-Inputs!$B$47),0) | K5: =IF(AND(9>=Inputs!$B$49,9<Inputs!$B$49+Inputs!$B$50),PMT(Inputs!$B$48,Inputs!$B$50,-Inputs!$B$47),0) | L5: =IF(AND(10>=Inputs!$B$49,10<Inputs!$B$49+Inputs!$B$50),PMT(Inputs!$B$48,Inputs!$B$50,-Inputs!$B$47),0)
A6: Interest | B6: =B4*Inputs!$B$48*0.5 | C6: =C3*Inputs!$B$48 | D6: =D3*Inputs!$B$48 | E6: =E3*Inputs!$B$48 | F6: =F3*Inputs!$B$48 | G6: =G3*Inputs!$B$48 | H6: =H3*Inputs!$B$48 | I6: =I3*Inputs!$B$48 | J6: =J3*Inputs!$B$48 | ... L6: =L3*Inputs!$B$48
A7: Principal | B7: =IF(B5>0,B5-B6,0) | C7: =IF(C5>0,C5-C6,0) | D7: =IF(D5>0,D5-D6,0) | E7: =IF(E5>0,E5-E6,0) | F7: =IF(F5>0,F5-F6,0) | G7: =IF(G5>0,G5-G6,0) | H7: =IF(H5>0,H5-H6,0) | I7: =IF(I5>0,I5-I6,0) | ... L7: =IF(L5>0,L5-L6,0)
A8: Closing balance | B8: =B3+B4-B7 | C8: =C3+C4-C7 | D8: =D3+D4-D7 | E8: =E3+E4-E7 | F8: =F3+F4-F7 | G8: =G3+G4-G7 | H8: =H3+H4-H7 | I8: =I3+I4-I7 | ... L8: =L3+L4-L7
A10: T2 Islamic / commercial | B10: 2028 | C10: 2029 | D10: 2030 | E10: 2031 | F10: 2032 | G10: 2033 | H10: 2034 | I10: 2035 | J10: 2036 | K10: 2037 | L10: 2038
A11: Opening balance | B11: =0 | C11: =B16 | D11: =C16 | E11: =D16 | F11: =E16 | G11: =F16 | H11: =G16 | I11: =H16 | J11: =I16 | ... L11: =K16
A12: Drawdown | B12: =Inputs!$B$51 | C12: =0 | D12: =0 | E12: =0 | F12: =0 | G12: =0 | H12: =0 | I12: =0 | J12: =0 | ... L12: =0
A13: Installment | B13: =0 | C13: =IF(AND(1>=Inputs!$B$53,1<Inputs!$B$53+Inputs!$B$54),PMT(Inputs!$B$52,Inputs!$B$54,-Inputs!$B$51),0) | D13: =IF(AND(2>=Inputs!$B$53,2<Inputs!$B$53+Inputs!$B$54),PMT(Inputs!$B$52,Inputs!$B$54,-Inputs!$B$51),0) | E13: =IF(AND(3>=Inputs!$B$53,3<Inputs!$B$53+Inputs!$B$54),PMT(Inputs!$B$52,Inputs!$B$54,-Inputs!$B$51),0) | F13: =IF(AND(4>=Inputs!$B$53,4<Inputs!$B$53+Inputs!$B$54),PMT(Inputs!$B$52,Inputs!$B$54,-Inputs!$B$51),0) | G13: =IF(AND(5>=Inputs!$B$53,5<Inputs!$B$53+Inputs!$B$54),PMT(Inputs!$B$52,Inputs!$B$54,-Inputs!$B$51),0) | H13: =IF(AND(6>=Inputs!$B$53,6<Inputs!$B$53+Inputs!$B$54),PMT(Inputs!$B$52,Inputs!$B$54,-Inputs!$B$51),0) | I13: =IF(AND(7>=Inputs!$B$53,7<Inputs!$B$53+Inputs!$B$54),PMT(Inputs!$B$52,Inputs!$B$54,-Inputs!$B$51),0) | J13: =IF(AND(8>=Inputs!$B$53,8<Inputs!$B$53+Inputs!$B$54),PMT(Inputs!$B$52,Inputs!$B$54,-Inputs!$B$51),0) | K13: =IF(AND(9>=Inputs!$B$53,9<Inputs!$B$53+Inputs!$B$54),PMT(Inputs!$B$52,Inputs!$B$54,-Inputs!$B$51),0) | L13: =IF(AND(10>=Inputs!$B$53,10<Inputs!$B$53+Inputs!$B$54),PMT(Inputs!$B$52,Inputs!$B$54,-Inputs!$B$51),0)
A14: Interest | B14: =B12*Inputs!$B$52*0.5 | C14: =C11*Inputs!$B$52 | D14: =D11*Inputs!$B$52 | E14: =E11*Inputs!$B$52 | F14: =F11*Inputs!$B$52 | G14: =G11*Inputs!$B$52 | H14: =H11*Inputs!$B$52 | I14: =I11*Inputs!$B$52 | J14: =J11*Inputs!$B$52 | ... L14: =L11*Inputs!$B$52
A15: Principal | B15: =IF(B13>0,B13-B14,0) | C15: =IF(C13>0,C13-C14,0) | D15: =IF(D13>0,D13-D14,0) | E15: =IF(E13>0,E13-E14,0) | F15: =IF(F13>0,F13-F14,0) | G15: =IF(G13>0,G13-G14,0) | H15: =IF(H13>0,H13-H14,0) | I15: =IF(I13>0,I13-I14,0) | ... L15: =IF(L13>0,L13-L14,0)
A16: Closing balance | B16: =B11+B12-B15 | C16: =C11+C12-C15 | D16: =D11+D12-D15 | E16: =E11+E12-E15 | F16: =F11+F12-F15 | G16: =G11+G12-G15 | H16: =H11+H12-H15 | I16: =I11+I12-I15 | ... L16: =L11+L12-L15
A18: T3 Equipment finance lease | B18: 2028 | C18: 2029 | D18: 2030 | E18: 2031 | F18: 2032 | G18: 2033 | H18: 2034 | I18: 2035 | J18: 2036 | K18: 2037 | L18: 2038
A19: Opening balance | B19: =0 | C19: =B24 | D19: =C24 | E19: =D24 | F19: =E24 | G19: =F24 | H19: =G24 | I19: =H24 | J19: =I24 | ... L19: =K24
A20: Drawdown | B20: =Inputs!$B$55 | C20: =0 | D20: =0 | E20: =0 | F20: =0 | G20: =0 | H20: =0 | I20: =0 | J20: =0 | ... L20: =0
A21: Installment | B21: =0 | C21: =IF(1<=Inputs!$B$57,PMT(Inputs!$B$56,Inputs!$B$57,-Inputs!$B$55),0) | D21: =IF(2<=Inputs!$B$57,PMT(Inputs!$B$56,Inputs!$B$57,-Inputs!$B$55),0) | E21: =IF(3<=Inputs!$B$57,PMT(Inputs!$B$56,Inputs!$B$57,-Inputs!$B$55),0) | F21: =IF(4<=Inputs!$B$57,PMT(Inputs!$B$56,Inputs!$B$57,-Inputs!$B$55),0) | G21: =IF(5<=Inputs!$B$57,PMT(Inputs!$B$56,Inputs!$B$57,-Inputs!$B$55),0) | H21: =IF(6<=Inputs!$B$57,PMT(Inputs!$B$56,Inputs!$B$57,-Inputs!$B$55),0) | I21: =IF(7<=Inputs!$B$57,PMT(Inputs!$B$56,Inputs!$B$57,-Inputs!$B$55),0) | J21: =IF(8<=Inputs!$B$57,PMT(Inputs!$B$56,Inputs!$B$57,-Inputs!$B$55),0) | K21: =IF(9<=Inputs!$B$57,PMT(Inputs!$B$56,Inputs!$B$57,-Inputs!$B$55),0) | L21: =IF(10<=Inputs!$B$57,PMT(Inputs!$B$56,Inputs!$B$57,-Inputs!$B$55),0)
A22: Interest | B22: =0 | C22: =IF(1<=Inputs!$B$57,C19*Inputs!$B$56,0) | D22: =IF(2<=Inputs!$B$57,D19*Inputs!$B$56,0) | E22: =IF(3<=Inputs!$B$57,E19*Inputs!$B$56,0) | F22: =IF(4<=Inputs!$B$57,F19*Inputs!$B$56,0) | G22: =IF(5<=Inputs!$B$57,G19*Inputs!$B$56,0) | H22: =IF(6<=Inputs!$B$57,H19*Inputs!$B$56,0) | I22: =IF(7<=Inputs!$B$57,I19*Inputs!$B$56,0) | J22: =IF(8<=Inputs!$B$57,J19*Inputs!$B$56,0) | K22: =IF(9<=Inputs!$B$57,K19*Inputs!$B$56,0) | L22: =IF(10<=Inputs!$B$57,L19*Inputs!$B$56,0)
A23: Principal | B23: =IF(B21>0,B21-B22,0) | C23: =IF(C21>0,C21-C22,0) | D23: =IF(D21>0,D21-D22,0) | E23: =IF(E21>0,E21-E22,0) | F23: =IF(F21>0,F21-F22,0) | G23: =IF(G21>0,G21-G22,0) | H23: =IF(H21>0,H21-H22,0) | I23: =IF(I21>0,I21-I22,0) | ... L23: =IF(L21>0,L21-L22,0)
A24: Closing balance | B24: =B19+B20-B23 | C24: =C19+C20-C23 | D24: =D19+D20-D23 | E24: =E19+E20-E23 | F24: =F19+F20-F23 | G24: =G19+G20-G23 | H24: =H19+H20-H23 | I24: =I19+I20-I23 | ... L24: =L19+L20-L23

Sheet CashFlow
A1: Cash flow, DSCR and valuation (live formulas)
A2: Year | B2: 2029 | C2: 2030 | D2: 2031 | E2: 2032 | F2: 2033 | G2: 2034 | H2: 2035 | I2: 2036 | J2: 2037 | K2: 2038
A3: EBITDA | B3: =PnL!B33 | C3: =PnL!C33 | D3: =PnL!D33 | E3: =PnL!E33 | F3: =PnL!F33 | G3: =PnL!G33 | H3: =PnL!H33 | I3: =PnL!I33 | ... K3: =PnL!K33
A4: Tax | B4: =PnL!B40 | C4: =PnL!C40 | D4: =PnL!D40 | E4: =PnL!E40 | F4: =PnL!F40 | G4: =PnL!G40 | H4: =PnL!H40 | I4: =PnL!I40 | ... K4: =PnL!K40
A5: Receivables | B5: =PnL!B17*Inputs!$B$39/365 | C5: =PnL!C17*Inputs!$B$39/365 | D5: =PnL!D17*Inputs!$B$39/365 | E5: =PnL!E17*Inputs!$B$39/365 | F5: =PnL!F17*Inputs!$B$39/365 | G5: =PnL!G17*Inputs!$B$39/365 | H5: =PnL!H17*Inputs!$B$39/365 | I5: =PnL!I17*Inputs!$B$39/365 | ... K5: =PnL!K17*Inputs!$B$39/365
A6: Inventory | B6: =(PnL!B19+PnL!B20)*Inputs!$B$40/365 | C6: =(PnL!C19+PnL!C20)*Inputs!$B$40/365 | D6: =(PnL!D19+PnL!D20)*Inputs!$B$40/365 | E6: =(PnL!E19+PnL!E20)*Inputs!$B$40/365 | F6: =(PnL!F19+PnL!F20)*Inputs!$B$40/365 | G6: =(PnL!G19+PnL!G20)*Inputs!$B$40/365 | H6: =(PnL!H19+PnL!H20)*Inputs!$B$40/365 | I6: =(PnL!I19+PnL!I20)*Inputs!$B$40/365 | ... K6: =(PnL!K19+PnL!K20)*Inputs!$B$40/365
A7: Payables | B7: =(PnL!B32-PnL!B18-PnL!B31-PnL!B21)*Inputs!$B$41/365 | C7: =(PnL!C32-PnL!C18-PnL!C31-PnL!C21)*Inputs!$B$41/365 | D7: =(PnL!D32-PnL!D18-PnL!D31-PnL!D21)*Inputs!$B$41/365 | E7: =(PnL!E32-PnL!E18-PnL!E31-PnL!E21)*Inputs!$B$41/365 | F7: =(PnL!F32-PnL!F18-PnL!F31-PnL!F21)*Inputs!$B$41/365 | G7: =(PnL!G32-PnL!G18-PnL!G31-PnL!G21)*Inputs!$B$41/365 | H7: =(PnL!H32-PnL!H18-PnL!H31-PnL!H21)*Inputs!$B$41/365 | I7: =(PnL!I32-PnL!I18-PnL!I31-PnL!I21)*Inputs!$B$41/365 | ... K7: =(PnL!K32-PnL!K18-PnL!K31-PnL!K21)*Inputs!$B$41/365
A8: Net working capital | B8: =B5+B6-B7 | C8: =C5+C6-C7 | D8: =D5+D6-D7 | E8: =E5+E6-E7 | F8: =F5+F6-F7 | G8: =G5+G6-G7 | H8: =H5+H6-H7 | I8: =I5+I6-I7 | ... K8: =K5+K6-K7
A9: Change in working capital | B9: =B8 | C9: =C8-B8 | D9: =D8-C8 | E9: =E8-D8 | F9: =F8-E8 | G9: =G8-F8 | H9: =H8-G8 | I9: =I8-H8 | J9: =J8-I8 | K9: =K8-J8
A10: Maintenance capex | B10: =PnL!B35 | C10: =PnL!C35 | D10: =PnL!D35 | E10: =PnL!E35 | F10: =PnL!F35 | G10: =PnL!G35 | H10: =PnL!H35 | I10: =PnL!I35 | ... K10: =PnL!K35
A11: CFADS | B11: =B3-B4-B9-B10 | C11: =C3-C4-C9-C10 | D11: =D3-D4-D9-D10 | E11: =E3-E4-E9-E10 | F11: =F3-F4-F9-F10 | G11: =G3-G4-G9-G10 | H11: =H3-H4-H9-H10 | I11: =I3-I4-I9-I10 | ... K11: =K3-K4-K9-K10
A12: Debt service | B12: =Debt!C5+Debt!C13+Debt!C21+IF(Debt!C5=0,Debt!C6,0)+IF(Debt!C13=0,Debt!C14,0) | C12: =Debt!D5+Debt!D13+Debt!D21+IF(Debt!D5=0,Debt!D6,0)+IF(Debt!D13=0,Debt!D14,0) | D12: =Debt!E5+Debt!E13+Debt!E21+IF(Debt!E5=0,Debt!E6,0)+IF(Debt!E13=0,Debt!E14,0) | E12: =Debt!F5+Debt!F13+Debt!F21+IF(Debt!F5=0,Debt!F6,0)+IF(Debt!F13=0,Debt!F14,0) | F12: =Debt!G5+Debt!G13+Debt!G21+IF(Debt!G5=0,Debt!G6,0)+IF(Debt!G13=0,Debt!G14,0) | G12: =Debt!H5+Debt!H13+Debt!H21+IF(Debt!H5=0,Debt!H6,0)+IF(Debt!H13=0,Debt!H14,0) | H12: =Debt!I5+Debt!I13+Debt!I21+IF(Debt!I5=0,Debt!I6,0)+IF(Debt!I13=0,Debt!I14,0) | I12: =Debt!J5+Debt!J13+Debt!J21+IF(Debt!J5=0,Debt!J6,0)+IF(Debt!J13=0,Debt!J14,0) | ... K12: =Debt!L5+Debt!L13+Debt!L21+IF(Debt!L5=0,Debt!L6,0)+IF(Debt!L13=0,Debt!L14,0)
A13: DSCR | B13: =IF(B12>0,B11/B12,"") | C13: =IF(C12>0,C11/C12,"") | D13: =IF(D12>0,D11/D12,"") | E13: =IF(E12>0,E11/E12,"") | F13: =IF(F12>0,F11/F12,"") | G13: =IF(G12>0,G11/G12,"") | H13: =IF(H12>0,H11/H12,"") | I13: =IF(I12>0,I11/I12,"") | ... K13: =IF(K12>0,K11/K12,"")
A14: Cash flow after debt service | B14: =B11-B12 | C14: =C11-C12 | D14: =D11-D12 | E14: =E11-E12 | F14: =F11-F12 | G14: =G11-G12 | H14: =H11-H12 | I14: =I11-I12 | ... K14: =K11-K12
A15: Closing cash (from reserve) | B15: =Inputs!$B$58+B14 | C15: =B15+C14 | D15: =C15+D14 | E15: =D15+E14 | F15: =E15+F14 | G15: =F15+G14 | H15: =G15+H14 | I15: =H15+I14 | J15: =I15+J14 | K15: =J15+K14
A16: Unlevered tax | B16: =MAX(PnL!B33-PnL!B36,0)*Inputs!$B$42*IF(Drivers!B$16<Inputs!$B$44,1-Inputs!$B$43,1) | C16: =MAX(PnL!C33-PnL!C36,0)*Inputs!$B$42*IF(Drivers!C$16<Inputs!$B$44,1-Inputs!$B$43,1) | D16: =MAX(PnL!D33-PnL!D36,0)*Inputs!$B$42*IF(Drivers!D$16<Inputs!$B$44,1-Inputs!$B$43,1) | E16: =MAX(PnL!E33-PnL!E36,0)*Inputs!$B$42*IF(Drivers!E$16<Inputs!$B$44,1-Inputs!$B$43,1) | F16: =MAX(PnL!F33-PnL!F36,0)*Inputs!$B$42*IF(Drivers!F$16<Inputs!$B$44,1-Inputs!$B$43,1) | G16: =MAX(PnL!G33-PnL!G36,0)*Inputs!$B$42*IF(Drivers!G$16<Inputs!$B$44,1-Inputs!$B$43,1) | H16: =MAX(PnL!H33-PnL!H36,0)*Inputs!$B$42*IF(Drivers!H$16<Inputs!$B$44,1-Inputs!$B$43,1) | I16: =MAX(PnL!I33-PnL!I36,0)*Inputs!$B$42*IF(Drivers!I$16<Inputs!$B$44,1-Inputs!$B$43,1) | ... K16: =MAX(PnL!K33-PnL!K36,0)*Inputs!$B$42*IF(Drivers!K$16<Inputs!$B$44,1-Inputs!$B$43,1)
A17: Project free cash flow | B17: =B3-B16-B9-B10 | C17: =C3-C16-C9-C10 | D17: =D3-D16-D9-D10 | E17: =E3-E16-E9-E10 | F17: =F3-F16-F9-F10 | G17: =G3-G16-G9-G10 | H17: =H3-H16-H9-H10 | I17: =I3-I16-I9-I10 | ... K17: =K3-K16-K9-K10
A19: Construction outflow 2027 | B19: -924720
A20: Construction outflow 2028 | B20: -3327080
A21: Terminal value at 2038 | B21: =K17*(1+Inputs!$B$46)/(Inputs!$B$45-Inputs!$B$46)
A22: Project NPV @ discount rate, no TV | B22: =B19+B20/(1+Inputs!$B$45)+NPV(Inputs!$B$45,B17:K17)/(1+Inputs!$B$45)
A23: Project NPV with TV | B23: =B22+B21/(1+Inputs!$B$45)^11
A24: Minimum DSCR | B24: =MIN(B13:K13)
A25: Minimum cash | B25: =MIN(B15:K15)
A26: Python check: NPV with TV (should match) | B26: 2583075

Sheet Scenarios
A1: Scenario and structure results (values from ptc_model.py)
A2: Case | B2: net_rev_y6 | C2: ebitda_y6 | D2: ebitda_margin_y6 | E2: min_dscr | F2: min_dscr_year | G2: dscr_y6 | H2: min_cash | I2: npv_no_tv | J2: npv_tv | K2: irr_tv | L2: equity_irr_tv | M2: equity | N2: debt
A3: Base | B3: 4816039.6 | C3: 1144957.8 | D3: 0.2377 | E3: -3.0088 | F3: 2029 | G3: 2.2951 | H3: -806818.36 | I3: -1502654.4 | J3: 2583075.2 | K3: 0.1604 | L3: 0.1814 | M3: 2011175 | N3: 3000000
A4: Prudent (volumes -20%, prices -5%, DSO 150) | B4: 3687996.4 | C4: 338526.58 | D4: 0.0918 | E4: -4.8477 | F4: 2029 | G4: 0.5781 | H4: -3700946.7 | I4: -4872095.4 | J4: -3873944.8 | K4: -0.0436 | L4: -0.063 | M4: 2011175 | N4: 3000000
A5: Optimistic (volumes +15%) | B5: 5516493.2 | C5: 1643938.7 | D5: 0.298 | E5: -2.4213 | F5: 2029 | G5: 3.314 | H5: -238985 | I5: 337982.31 | J5: 6312687.8 | K5: 0.2278 | L5: 0.2656 | M5: 2011175 | N5: 3000000
A6: Tourism shock (tourists -80% Y1-Y2, ER -10%) | B6: 4734075.7 | C6: 1084276 | D6: 0.229 | E6: -3.2553 | F6: 2029 | G6: 2.319 | H6: -1025920.2 | I6: -1831100.8 | J6: 2014566.4 | K6: 0.1478 | L6: 0.1663 | M6: 2011175 | N6: 3000000
A7: No customs/sales-tax exemption (+16% on equipment and MEP) | B7: 4816039.6 | C7: 1129425.8 | D7: 0.2345 | E7: -3.0265 | F7: 2029 | G7: 2.3795 | H7: -828136.83 | I7: -1842591.9 | J7: 2188369.7 | K7: 0.1496 | L7: 0.1672 | M7: 2334855 | N7: 3000000
A8: Construction 780/m2 (+30% on lean 600) | B8: 4816039.6 | C8: 1138815.6 | D8: 0.2365 | E8: -3.0298 | F8: 2029 | G8: 2.3036 | H8: -822577.72 | I8: -2035930.7 | J8: 2041423.6 | K8: 0.1447 | L8: 0.16 | M8: 2554055 | N8: 3000000
A9: Payroll +15% | B9: 4816039.6 | C9: 919903.75 | D9: 0.191 | E9: -3.6838 | F9: 2029 | G9: 2.1326 | H9: -1407774.1 | I9: -2520876 | J9: 670614.97 | K9: 0.117 | L9: 0.1298 | M9: 2011175 | N9: 3000000
A10: MoH/RMS purchasing contract (+15% inpatient and surgery, DSO 150) | B10: 5100583.1 | C10: 1342126.2 | D10: 0.2631 | E10: -3.985 | F10: 2029 | G10: 2.6093 | H10: -979403.29 | I10: -1251698.7 | J10: 3514378.9 | K10: 0.1755 | L10: 0.1985 | M10: 2011175 | N10: 3000000
A11: Conditions met: contracted volumes +20% | B11: 5749977.7 | C11: 1810265.7 | D11: 0.3148 | E11: -2.2255 | F11: 2029 | G11: 3.6536 | H11: -109372.69 | I11: 950162.83 | J11: 7554527 | K11: 0.2471 | L11: 0.2901 | M11: 2011175 | N11: 3000000
A12: If MoH requires a general hospital (40 beds, internal medicine + obstetrics) | B12: 5653873.8 | C12: 1037959.9 | D12: 0.1836 | E12: -4.4311 | F12: 2029 | G12: 2.3905 | H12: -1627738.8 | I12: -5527063.9 | J12: -1925167.7 | K12: 0.0664 | L12: 0.0698 | M12: 5358775 | N12: 3000000
A13: F1 CBJ 2.5m + equipment lease 0.5m + equity | B13: 4816039.6 | C13: 1144957.8 | D13: 0.2377 | E13: -3.0088 | F13: 2029 | G13: 2.2951 | H13: -806818.36 | I13: -1502654.4 | J13: 2583075.2 | K13: 0.1604 | L13: 0.1814 | M13: 2011175 | N13: 3000000
A14: F2 CBJ 2.5m + Islamic ijara 1.2m + lease 0.5m + equity | B14: 4816039.6 | C14: 1144957.8 | D14: 0.2377 | E14: -2.123 | F14: 2029 | G14: 1.6049 | H14: -1389033.7 | I14: -1502654.4 | J14: 2583075.2 | K14: 0.1604 | L14: 0.2014 | M14: 862175 | N14: 4200000
... A16: F4 Doctor-investor company: CBJ 2.0m + lease 0.5m, more equity from 10-15 doctors | B16: 4816039.6 | C16: 1144957.8 | D16: 0.2377 | E16: -3.2953 | F16: 2029 | G16: 2.8617 | H16: -641069.96 | I16: -1502654.4 | J16: 2583075.2 | K16: 0.1604 | L16: 0.1732 | M16: 2499300 | N16: 2500000

Sheet Vs_reference_study
A1: Comparison with the owner-supplied reference study (Ennab 2025, 80-bed general hospital, Wadi Musa)
A3: Metric | B3: Reference study (80 beds) | C3: This study (20 beds, lean Phase 1)
A4: Total investment JOD | B4: 7574640 | C4: 5011175
A5: Investment per bed | B5: 94683 | C5: 250559
A6: Building cost per m2 (structure+finishing) | B6: 298 | C6: 600
A7: Medical equipment JOD | B7: 3150400 | C7: 1300000
A8: Staff | B8: 100 | C8: 96
A9: Annual payroll Y1 JOD | B9: 609960 | C9: 970668
A10: Average monthly cost per employee | B10: 508 | C10: 1123
A11: Revenue Y1 JOD | B11: 3311250 | C11: 2017116
A12: Revenue ramp-up | B12: none (+3%/yr) | C12: 38% -> 72% ward occupancy over 6 years
A13: Debt | B13: none | C13: 3000000
A14: Receivables | B14: ignored (all cash) | C14: 105 days
A15: Net profit Y1 JOD | B15: 150054 | C15: -703566
