Workbook

Sheet Inputs
A1: Input | B1: Value | C1: Basis
A2: Loan amount (JOD) | B2: 165000 | C2: [SOURCE: owner brief] 160k long-term + 40k working capital
A3: Annual rate | B3: 0.0325 | C3: [SOURCE: HBTF CBJ sectors programme page: outside Amman 0.5% + margin, min 3.25%][VERIFY bank offer]
A4: Grace months (interest only) | B4: 12 | C4: [SOURCE: owner brief; programme allows up to 24]
A5: Repayment months | B5: 108 | C5: [SOURCE: owner brief]
A6: Tax rate | B6: 0.2 | C6: [ASSUMPTION per brief][VERIFY individual vs company basis]
A7: Depreciable CAPEX (BOQ + contingency) | B7: 159266.1 | C7: [SOURCE: BOQ 151,682 + 5% 7,584.10]
A8: Depreciation years | B8: 20 | C8: [ASSUMPTION] lease term 20 years
A9: Opening cash reserves | B9: 24629 | C9: [SOURCE: brief uses] 36,104.90 + 12,300 + 12,329
A12: Yellow cells are inputs. Change them and the Debt and CashFlow sheets recalculate (debt service, tax, DSCR).

Sheet Debt
A1: Month | B1: Year | C1: Opening balance | D1: Interest | E1: Principal | F1: Payment | G1: Closing balance | I1: Level payment after grace | J1: =PMT(Inputs!B3/12,Inputs!B5,-Inputs!B2) -> 1764.1456
A2: 1 | B2: =INT((A2-1)/12)+1 -> 1 | C2: =Inputs!B2 -> 165000 | D2: =C2*Inputs!B3/12 -> 446.875 | E2: =IF(A2<=Inputs!B4,0,MIN($J$1-D2,C2)) -> 0 | F2: =D2+E2 -> 446.875 | G2: =C2-E2 -> 165000
A3: 2 | B3: =INT((A3-1)/12)+1 -> 1 | C3: =G2 -> 165000 | D3: =C3*Inputs!B3/12 -> 446.875 | E3: =IF(A3<=Inputs!B4,0,MIN($J$1-D3,C3)) -> 0 | F3: =D3+E3 -> 446.875 | G3: =C3-E3 -> 165000
A4: 3 | B4: =INT((A4-1)/12)+1 -> 1 | C4: =G3 -> 165000 | D4: =C4*Inputs!B3/12 -> 446.875 | E4: =IF(A4<=Inputs!B4,0,MIN($J$1-D4,C4)) -> 0 | F4: =D4+E4 -> 446.875 | G4: =C4-E4 -> 165000
A5: 4 | B5: =INT((A5-1)/12)+1 -> 1 | C5: =G4 -> 165000 | D5: =C5*Inputs!B3/12 -> 446.875 | E5: =IF(A5<=Inputs!B4,0,MIN($J$1-D5,C5)) -> 0 | F5: =D5+E5 -> 446.875 | G5: =C5-E5 -> 165000
A6: 5 | B6: =INT((A6-1)/12)+1 -> 1 | C6: =G5 -> 165000 | D6: =C6*Inputs!B3/12 -> 446.875 | E6: =IF(A6<=Inputs!B4,0,MIN($J$1-D6,C6)) -> 0 | F6: =D6+E6 -> 446.875 | G6: =C6-E6 -> 165000
A7: 6 | B7: =INT((A7-1)/12)+1 -> 1 | C7: =G6 -> 165000 | D7: =C7*Inputs!B3/12 -> 446.875 | E7: =IF(A7<=Inputs!B4,0,MIN($J$1-D7,C7)) -> 0 | F7: =D7+E7 -> 446.875 | G7: =C7-E7 -> 165000
A8: 7 | B8: =INT((A8-1)/12)+1 -> 1 | C8: =G7 -> 165000 | D8: =C8*Inputs!B3/12 -> 446.875 | E8: =IF(A8<=Inputs!B4,0,MIN($J$1-D8,C8)) -> 0 | F8: =D8+E8 -> 446.875 | G8: =C8-E8 -> 165000
A9: 8 | B9: =INT((A9-1)/12)+1 -> 1 | C9: =G8 -> 165000 | D9: =C9*Inputs!B3/12 -> 446.875 | E9: =IF(A9<=Inputs!B4,0,MIN($J$1-D9,C9)) -> 0 | F9: =D9+E9 -> 446.875 | G9: =C9-E9 -> 165000
A10: 9 | B10: =INT((A10-1)/12)+1 -> 1 | C10: =G9 -> 165000 | D10: =C10*Inputs!B3/12 -> 446.875 | E10: =IF(A10<=Inputs!B4,0,MIN($J$1-D10,C10)) -> 0 | F10: =D10+E10 -> 446.875 | G10: =C10-E10 -> 165000
A11: 10 | B11: =INT((A11-1)/12)+1 -> 1 | C11: =G10 -> 165000 | D11: =C11*Inputs!B3/12 -> 446.875 | E11: =IF(A11<=Inputs!B4,0,MIN($J$1-D11,C11)) -> 0 | F11: =D11+E11 -> 446.875 | G11: =C11-E11 -> 165000
A12: 11 | B12: =INT((A12-1)/12)+1 -> 1 | C12: =G11 -> 165000 | D12: =C12*Inputs!B3/12 -> 446.875 | E12: =IF(A12<=Inputs!B4,0,MIN($J$1-D12,C12)) -> 0 | F12: =D12+E12 -> 446.875 | G12: =C12-E12 -> 165000
A13: 12 | B13: =INT((A13-1)/12)+1 -> 1 | C13: =G12 -> 165000 | D13: =C13*Inputs!B3/12 -> 446.875 | E13: =IF(A13<=Inputs!B4,0,MIN($J$1-D13,C13)) -> 0 | F13: =D13+E13 -> 446.875 | G13: =C13-E13 -> 165000
A14: 13 | B14: =INT((A14-1)/12)+1 -> 2 | C14: =G13 -> 165000 | D14: =C14*Inputs!B3/12 -> 446.875 | E14: =IF(A14<=Inputs!B4,0,MIN($J$1-D14,C14)) -> 1317.2706 | F14: =D14+E14 -> 1764.1456 | G14: =C14-E14 -> 163682.73
A15: 14 | B15: =INT((A15-1)/12)+1 -> 2 | C15: =G14 -> 163682.73 | D15: =C15*Inputs!B3/12 -> 443.30739 | E15: =IF(A15<=Inputs!B4,0,MIN($J$1-D15,C15)) -> 1320.8382 | F15: =D15+E15 -> 1764.1456 | G15: =C15-E15 -> 162361.89
A16: 15 | B16: =INT((A16-1)/12)+1 -> 2 | C16: =G15 -> 162361.89 | D16: =C16*Inputs!B3/12 -> 439.73012 | E16: =IF(A16<=Inputs!B4,0,MIN($J$1-D16,C16)) -> 1324.4155 | F16: =D16+E16 -> 1764.1456 | G16: =C16-E16 -> 161037.48
A17: 16 | B17: =INT((A17-1)/12)+1 -> 2 | C17: =G16 -> 161037.48 | D17: =C17*Inputs!B3/12 -> 436.14316 | E17: =IF(A17<=Inputs!B4,0,MIN($J$1-D17,C17)) -> 1328.0025 | F17: =D17+E17 -> 1764.1456 | G17: =C17-E17 -> 159709.47
A18: 17 | B18: =INT((A18-1)/12)+1 -> 2 | C18: =G17 -> 159709.47 | D18: =C18*Inputs!B3/12 -> 432.54649 | E18: =IF(A18<=Inputs!B4,0,MIN($J$1-D18,C18)) -> 1331.5991 | F18: =D18+E18 -> 1764.1456 | G18: =C18-E18 -> 158377.87
A19: 18 | B19: =INT((A19-1)/12)+1 -> 2 | C19: =G18 -> 158377.87 | D19: =C19*Inputs!B3/12 -> 428.94008 | E19: =IF(A19<=Inputs!B4,0,MIN($J$1-D19,C19)) -> 1335.2056 | F19: =D19+E19 -> 1764.1456 | G19: =C19-E19 -> 157042.67
A20: 19 | B20: =INT((A20-1)/12)+1 -> 2 | C20: =G19 -> 157042.67 | D20: =C20*Inputs!B3/12 -> 425.32389 | E20: =IF(A20<=Inputs!B4,0,MIN($J$1-D20,C20)) -> 1338.8217 | F20: =D20+E20 -> 1764.1456 | G20: =C20-E20 -> 155703.85
A21: 20 | B21: =INT((A21-1)/12)+1 -> 2 | C21: =G20 -> 155703.85 | D21: =C21*Inputs!B3/12 -> 421.69792 | E21: =IF(A21<=Inputs!B4,0,MIN($J$1-D21,C21)) -> 1342.4477 | F21: =D21+E21 -> 1764.1456 | G21: =C21-E21 -> 154361.4
A22: 21 | B22: =INT((A22-1)/12)+1 -> 2 | C22: =G21 -> 154361.4 | D22: =C22*Inputs!B3/12 -> 418.06212 | E22: =IF(A22<=Inputs!B4,0,MIN($J$1-D22,C22)) -> 1346.0835 | F22: =D22+E22 -> 1764.1456 | G22: =C22-E22 -> 153015.32
A23: 22 | B23: =INT((A23-1)/12)+1 -> 2 | C23: =G22 -> 153015.32 | D23: =C23*Inputs!B3/12 -> 414.41648 | E23: =IF(A23<=Inputs!B4,0,MIN($J$1-D23,C23)) -> 1349.7291 | F23: =D23+E23 -> 1764.1456 | G23: =C23-E23 -> 151665.59
A24: 23 | B24: =INT((A24-1)/12)+1 -> 2 | C24: =G23 -> 151665.59 | D24: =C24*Inputs!B3/12 -> 410.76096 | E24: =IF(A24<=Inputs!B4,0,MIN($J$1-D24,C24)) -> 1353.3847 | F24: =D24+E24 -> 1764.1456 | G24: =C24-E24 -> 150312.2
A25: 24 | B25: =INT((A25-1)/12)+1 -> 2 | C25: =G24 -> 150312.2 | D25: =C25*Inputs!B3/12 -> 407.09555 | E25: =IF(A25<=Inputs!B4,0,MIN($J$1-D25,C25)) -> 1357.0501 | F25: =D25+E25 -> 1764.1456 | G25: =C25-E25 -> 148955.15
A26: 25 | B26: =INT((A26-1)/12)+1 -> 3 | C26: =G25 -> 148955.15 | D26: =C26*Inputs!B3/12 -> 403.4202 | E26: =IF(A26<=Inputs!B4,0,MIN($J$1-D26,C26)) -> 1360.7254 | F26: =D26+E26 -> 1764.1456 | G26: =C26-E26 -> 147594.43
A27: 26 | B27: =INT((A27-1)/12)+1 -> 3 | C27: =G26 -> 147594.43 | D27: =C27*Inputs!B3/12 -> 399.7349 | E27: =IF(A27<=Inputs!B4,0,MIN($J$1-D27,C27)) -> 1364.4107 | F27: =D27+E27 -> 1764.1456 | G27: =C27-E27 -> 146230.02
A28: 27 | B28: =INT((A28-1)/12)+1 -> 3 | C28: =G27 -> 146230.02 | D28: =C28*Inputs!B3/12 -> 396.03963 | E28: =IF(A28<=Inputs!B4,0,MIN($J$1-D28,C28)) -> 1368.106 | F28: =D28+E28 -> 1764.1456 | G28: =C28-E28 -> 144861.91
A29: 28 | B29: =INT((A29-1)/12)+1 -> 3 | C29: =G28 -> 144861.91 | D29: =C29*Inputs!B3/12 -> 392.33434 | E29: =IF(A29<=Inputs!B4,0,MIN($J$1-D29,C29)) -> 1371.8113 | F29: =D29+E29 -> 1764.1456 | G29: =C29-E29 -> 143490.1
A30: 29 | B30: =INT((A30-1)/12)+1 -> 3 | C30: =G29 -> 143490.1 | D30: =C30*Inputs!B3/12 -> 388.61902 | E30: =IF(A30<=Inputs!B4,0,MIN($J$1-D30,C30)) -> 1375.5266 | F30: =D30+E30 -> 1764.1456 | G30: =C30-E30 -> 142114.57
A31: 30 | B31: =INT((A31-1)/12)+1 -> 3 | C31: =G30 -> 142114.57 | D31: =C31*Inputs!B3/12 -> 384.89363 | E31: =IF(A31<=Inputs!B4,0,MIN($J$1-D31,C31)) -> 1379.252 | F31: =D31+E31 -> 1764.1456 | G31: =C31-E31 -> 140735.32
A32: 31 | B32: =INT((A32-1)/12)+1 -> 3 | C32: =G31 -> 140735.32 | D32: =C32*Inputs!B3/12 -> 381.15816 | E32: =IF(A32<=Inputs!B4,0,MIN($J$1-D32,C32)) -> 1382.9875 | F32: =D32+E32 -> 1764.1456 | G32: =C32-E32 -> 139352.33
A33: 32 | B33: =INT((A33-1)/12)+1 -> 3 | C33: =G32 -> 139352.33 | D33: =C33*Inputs!B3/12 -> 377.41257 | E33: =IF(A33<=Inputs!B4,0,MIN($J$1-D33,C33)) -> 1386.7331 | F33: =D33+E33 -> 1764.1456 | G33: =C33-E33 -> 137965.6
A34: 33 | B34: =INT((A34-1)/12)+1 -> 3 | C34: =G33 -> 137965.6 | D34: =C34*Inputs!B3/12 -> 373.65683 | E34: =IF(A34<=Inputs!B4,0,MIN($J$1-D34,C34)) -> 1390.4888 | F34: =D34+E34 -> 1764.1456 | G34: =C34-E34 -> 136575.11
A35: 34 | B35: =INT((A35-1)/12)+1 -> 3 | C35: =G34 -> 136575.11 | D35: =C35*Inputs!B3/12 -> 369.89092 | E35: =IF(A35<=Inputs!B4,0,MIN($J$1-D35,C35)) -> 1394.2547 | F35: =D35+E35 -> 1764.1456 | G35: =C35-E35 -> 135180.86
A36: 35 | B36: =INT((A36-1)/12)+1 -> 3 | C36: =G35 -> 135180.86 | D36: =C36*Inputs!B3/12 -> 366.11482 | E36: =IF(A36<=Inputs!B4,0,MIN($J$1-D36,C36)) -> 1398.0308 | F36: =D36+E36 -> 1764.1456 | G36: =C36-E36 -> 133782.82
A37: 36 | B37: =INT((A37-1)/12)+1 -> 3 | C37: =G36 -> 133782.82 | D37: =C37*Inputs!B3/12 -> 362.32848 | E37: =IF(A37<=Inputs!B4,0,MIN($J$1-D37,C37)) -> 1401.8171 | F37: =D37+E37 -> 1764.1456 | G37: =C37-E37 -> 132381.01
A38: 37 | B38: =INT((A38-1)/12)+1 -> 4 | C38: =G37 -> 132381.01 | D38: =C38*Inputs!B3/12 -> 358.5319 | E38: =IF(A38<=Inputs!B4,0,MIN($J$1-D38,C38)) -> 1405.6137 | F38: =D38+E38 -> 1764.1456 | G38: =C38-E38 -> 130975.39
A39: 38 | B39: =INT((A39-1)/12)+1 -> 4 | C39: =G38 -> 130975.39 | D39: =C39*Inputs!B3/12 -> 354.72503 | E39: =IF(A39<=Inputs!B4,0,MIN($J$1-D39,C39)) -> 1409.4206 | F39: =D39+E39 -> 1764.1456 | G39: =C39-E39 -> 129565.97
A40: 39 | B40: =INT((A40-1)/12)+1 -> 4 | C40: =G39 -> 129565.97 | D40: =C40*Inputs!B3/12 -> 350.90784 | E40: =IF(A40<=Inputs!B4,0,MIN($J$1-D40,C40)) -> 1413.2378 | F40: =D40+E40 -> 1764.1456 | G40: =C40-E40 -> 128152.74
...

Sheet CashFlow
A1: JOD, Year 1 = Mar 2027-Feb 2028 | B1: Y1 | C1: Y2 | D1: Y3 | E1: Y4 | F1: Y5 | G1: Y6 | H1: Y7 | I1: Y8 | J1: Y9 | K1: Y10
A2: Rent income | B2: 52846 | C2: 59063.17 | D2: 60244.44 | E2: 61449.32 | F2: 62678.31 | G2: 63931.88 | H2: 65210.51 | I2: 66514.72 | J2: 67845.02 | K2: 69201.92
A3: POS1 gallery (minimal, base) | B3: 14000 | C3: 15000 | D3: 15300 | E3: 15606 | F3: 15918.12 | G3: 16236.48 | H3: 16561.21 | I3: 16892.44 | J3: 17230.29 | K3: 17574.89
A4: POS2 crafts shop | B4: 21349 | C4: 23483.9 | D4: 24188.42 | E4: 24914.07 | F4: 25661.49 | G4: 26431.34 | H4: 27224.28 | I4: 28041 | J4: 28882.23 | K4: 29748.7
A5: POS2 cost of goods | B5: 8112.62 | C5: 7749.69 | D5: 7014.64 | E5: 7225.08 | F5: 7441.83 | G5: 7665.09 | H5: 7895.04 | I5: 8131.89 | J5: 8375.85 | K5: 8627.12
A6: Staff (payroll, 7th-day cover, guard) | B6: 39141.9 | C6: 40120.45 | D6: 41123.46 | E6: 42151.55 | F6: 43205.33 | G6: 44285.47 | H6: 45392.6 | I6: 46527.42 | J6: 47690.6 | K6: 48882.87
A7: Other OPEX (non-payroll, insurance, fees, maintenance) | B7: 9080 | C7: 10844.5 | D7: 11115.61 | E7: 11393.5 | F7: 11678.34 | G7: 11970.3 | H7: 12269.56 | I7: 12576.3 | J7: 12890.7 | K7: 13212.97
A8: Hotel & guide commissions 3% POS | B8: 1060.47 | C8: 1154.52 | D8: 1184.65 | E8: 1215.6 | F8: 1247.39 | G8: 1280.03 | H8: 1313.56 | I8: 1348 | J8: 1383.38 | K8: 1419.71
A9: Card fees 1.5% POS | B9: 530.24 | C9: 577.26 | D9: 592.33 | E9: 607.8 | F9: 623.69 | G9: 640.02 | H9: 656.78 | I9: 674 | J9: 691.69 | K9: 709.85
A10: Revenue | B10: =B2+B3+B4 -> 88195 | C10: =C2+C3+C4 -> 97547.07 | D10: =D2+D3+D4 -> 99732.86 | E10: =E2+E3+E4 -> 101969.39 | F10: =F2+F3+F4 -> 104257.92 | G10: =G2+G3+G4 -> 106599.7 | H10: =H2+H3+H4 -> 108996 | I10: =I2+I3+I4 -> 111448.16 | ... K10: =K2+K3+K4 -> 116525.51
A11: EBITDA | B11: =B10-B5-B6-B7-B8-B9 -> 30269.77 | C11: =C10-C5-C6-C7-C8-C9 -> 37100.65 | D11: =D10-D5-D6-D7-D8-D9 -> 38702.17 | E11: =E10-E5-E6-E7-E8-E9 -> 39375.86 | F11: =F10-F5-F6-F7-F8-F9 -> 40061.34 | G11: =G10-G5-G6-G7-G8-G9 -> 40758.79 | H11: =H10-H5-H6-H7-H8-H9 -> 41468.46 | I11: =I10-I5-I6-I7-I8-I9 -> 42190.55 | ... K11: =K10-K5-K6-K7-K8-K9 -> 43672.99
A12: Depreciation | B12: =Inputs!$B$7/Inputs!$B$8 -> 7963.305 | C12: =Inputs!$B$7/Inputs!$B$8 -> 7963.305 | D12: =Inputs!$B$7/Inputs!$B$8 -> 7963.305 | E12: =Inputs!$B$7/Inputs!$B$8 -> 7963.305 | F12: =Inputs!$B$7/Inputs!$B$8 -> 7963.305 | G12: =Inputs!$B$7/Inputs!$B$8 -> 7963.305 | H12: =Inputs!$B$7/Inputs!$B$8 -> 7963.305 | I12: =Inputs!$B$7/Inputs!$B$8 -> 7963.305 | ... K12: =Inputs!$B$7/Inputs!$B$8 -> 7963.305
A13: Interest | B13: =SUMIF(Debt!$B:$B,1,Debt!$D:$D) -> 5362.5 | C13: =SUMIF(Debt!$B:$B,2,Debt!$D:$D) -> 5124.8992 | D13: =SUMIF(Debt!$B:$B,3,Debt!$D:$D) -> 4595.6035 | E13: =SUMIF(Debt!$B:$B,4,Debt!$D:$D) -> 4048.8471 | F13: =SUMIF(Debt!$B:$B,5,Debt!$D:$D) -> 3484.0541 | G13: =SUMIF(Debt!$B:$B,6,Debt!$D:$D) -> 2900.6294 | H13: =SUMIF(Debt!$B:$B,7,Debt!$D:$D) -> 2297.9584 | I13: =SUMIF(Debt!$B:$B,8,Debt!$D:$D) -> 1675.4062 | J13: =SUMIF(Debt!$B:$B,9,Debt!$D:$D) -> 1032.3169 | K13: =SUMIF(Debt!$B:$B,10,Debt!$D:$D) -> 368.01298
A14: Profit before tax | B14: =B11-B12-B13 -> 16943.965 | C14: =C11-C12-C13 -> 24012.446 | D14: =D11-D12-D13 -> 26143.262 | E14: =E11-E12-E13 -> 27363.708 | F14: =F11-F12-F13 -> 28613.981 | G14: =G11-G12-G13 -> 29894.856 | H14: =H11-H12-H13 -> 31207.197 | I14: =I11-I12-I13 -> 32551.839 | ... K14: =K11-K12-K13 -> 35341.672
A15: Tax loss brought forward | B15: =0 -> 0 | C15: =MAX(0,B15-B14) -> 0 | D15: =MAX(0,C15-C14) -> 0 | E15: =MAX(0,D15-D14) -> 0 | F15: =MAX(0,E15-E14) -> 0 | G15: =MAX(0,F15-F14) -> 0 | H15: =MAX(0,G15-G14) -> 0 | I15: =MAX(0,H15-H14) -> 0 | J15: =MAX(0,I15-I14) -> 0 | K15: =MAX(0,J15-J14) -> 0
A16: Income tax | B16: =MAX(0,B14-B15)*Inputs!$B$6 -> 3388.793 | C16: =MAX(0,C14-C15)*Inputs!$B$6 -> 4802.4892 | D16: =MAX(0,D14-D15)*Inputs!$B$6 -> 5228.6523 | E16: =MAX(0,E14-E15)*Inputs!$B$6 -> 5472.7416 | F16: =MAX(0,F14-F15)*Inputs!$B$6 -> 5722.7962 | G16: =MAX(0,G14-G15)*Inputs!$B$6 -> 5978.9711 | H16: =MAX(0,H14-H15)*Inputs!$B$6 -> 6241.4393 | I16: =MAX(0,I14-I15)*Inputs!$B$6 -> 6510.3678 | ... K16: =MAX(0,K14-K15)*Inputs!$B$6 -> 7068.3344
A17: Net profit | B17: =B14-B16 -> 13555.172 | C17: =C14-C16 -> 19209.957 | D17: =D14-D16 -> 20914.609 | E17: =E14-E16 -> 21890.966 | F17: =F14-F16 -> 22891.185 | G17: =G14-G16 -> 23915.884 | H17: =H14-H16 -> 24965.757 | I17: =I14-I16 -> 26041.471 | ... K17: =K14-K16 -> 28273.338
A18: CFADS (EBITDA - tax) | B18: =B11-B16 -> 26880.977 | C18: =C11-C16 -> 32298.161 | D18: =D11-D16 -> 33473.518 | E18: =E11-E16 -> 33903.118 | F18: =F11-F16 -> 34338.544 | G18: =G11-G16 -> 34779.819 | H18: =H11-H16 -> 35227.021 | I18: =I11-I16 -> 35680.182 | ... K18: =K11-K16 -> 36604.656
A19: Principal | B19: =SUMIF(Debt!$B:$B,1,Debt!$E:$E) -> 0 | C19: =SUMIF(Debt!$B:$B,2,Debt!$E:$E) -> 16044.848 | D19: =SUMIF(Debt!$B:$B,3,Debt!$E:$E) -> 16574.144 | E19: =SUMIF(Debt!$B:$B,4,Debt!$E:$E) -> 17120.9 | F19: =SUMIF(Debt!$B:$B,5,Debt!$E:$E) -> 17685.693 | G19: =SUMIF(Debt!$B:$B,6,Debt!$E:$E) -> 18269.118 | H19: =SUMIF(Debt!$B:$B,7,Debt!$E:$E) -> 18871.789 | I19: =SUMIF(Debt!$B:$B,8,Debt!$E:$E) -> 19494.341 | J19: =SUMIF(Debt!$B:$B,9,Debt!$E:$E) -> 20137.431 | K19: =SUMIF(Debt!$B:$B,10,Debt!$E:$E) -> 20801.735
A20: Debt service | B20: =B13+B19 -> 5362.5 | C20: =C13+C19 -> 21169.748 | D20: =D13+D19 -> 21169.748 | E20: =E13+E19 -> 21169.748 | F20: =F13+F19 -> 21169.748 | G20: =G13+G19 -> 21169.748 | H20: =H13+H19 -> 21169.748 | I20: =I13+I19 -> 21169.748 | ... K20: =K13+K19 -> 21169.748
A21: DSCR (CFADS / debt service) | B21: =IF(B20=0,"-",B18/B20) -> 5.0127696 | C21: =IF(C20=0,"-",C18/C20) -> 1.5256753 | D21: =IF(D20=0,"-",D18/D20) -> 1.5811959 | E21: =IF(E20=0,"-",E18/E20) -> 1.601489 | F21: =IF(F20=0,"-",F18/F20) -> 1.6220573 | G21: =IF(G20=0,"-",G18/G20) -> 1.6429019 | H21: =IF(H20=0,"-",H18/H20) -> 1.6640265 | I21: =IF(I20=0,"-",I18/I20) -> 1.6854326 | ... K21: =IF(K20=0,"-",K18/K20) -> 1.7291021
A22: Closing cash | B22: =Inputs!$B$9+B18-B20 -> 46147.477 | C22: =B22+C18-C20 -> 57275.89 | D22: =C22+D18-D20 -> 69579.66 | E22: =D22+E18-E20 -> 82313.031 | F22: =E22+F18-F20 -> 95481.828 | G22: =F22+G18-G20 -> 109091.9 | H22: =G22+H18-H20 -> 123149.17 | I22: =H22+I18-I20 -> 137659.61 | J22: =I22+J18-J20 -> 152629.24 | K22: =J22+K18-K20 -> 168064.15
A23: Rent cover of debt service | B23: =IF(B20=0,"-",B2/B20) -> 9.8547319 | C23: =IF(C20=0,"-",C2/C20) -> 2.7899799 | D23: =IF(D20=0,"-",D2/D20) -> 2.8457798 | E23: =IF(E20=0,"-",E2/E20) -> 2.902695 | F23: =IF(F20=0,"-",F2/F20) -> 2.9607491 | G23: =IF(G20=0,"-",G2/G20) -> 3.0199642 | H23: =IF(H20=0,"-",H2/H20) -> 3.0803631 | I23: =IF(I20=0,"-",I2/I20) -> 3.1419704 | ... K23: =IF(K20=0,"-",K2/K20) -> 3.2689062

Sheet Funding options
A1: Case | B1: Total debt | C1: Monthly payment | D1: DSCR Y2 | E1: Min DSCR Y2-10 | F1: Avg DSCR | G1: DSCR Y10 | H1: Min closing cash | I1: Total interest 10y | J1: DSCR Y1 | K1: DSCR Y2 | L1: DSCR Y3 | M1: DSCR Y4 | N1: DSCR Y5 | O1: DSCR Y6 | P1: DSCR Y7 | Q1: DSCR Y8 | R1: DSCR Y9 | S1: DSCR Y10
A2: F0 CBJ working case (brief): 200k @3.00%, 12m grace + 108 | B2: 200000 | C2: 2115.3881 | D2: 1.2771272 | E2: 1.2771272 | F2: 1.3701681 | G2: 1.4423121 | H2: 81742.378 | I2: 34461.912 | J2: 4.501413 | K2: 1.2771272 | L2: 1.3228889 | M2: 1.3392676 | N2: 1.3558697 | O2: 1.3726974 | P2: 1.3897531 | Q2: 1.4070392 | R2: 1.4245581 | S2: 1.4423121
A3: F1 Brief structure at verified floor: 200k CBJ sectors programme @3.25%, 12m grace + 108 | B3: 200000 | C3: 2138.3583 | D3: 1.2671555 | E3: 1.2671555 | F3: 1.3575982 | G3: 1.4271176 | H3: 81342.378 | I3: 37442.7 | J3: 4.170535 | K3: 1.2671555 | L3: 1.3120843 | M3: 1.3279225 | N3: 1.3439573 | O3: 1.3601897 | P3: 1.3766209 | Q3: 1.393252 | R3: 1.4100839 | S3: 1.4271176
A4: F5 RECOMMENDED: 165k CBJ sectors programme @3.25%, 12m grace + 108 (no Y1 opex reserve) | B4: 165000 | C4: 1764.1456 | D4: 1.5256757 | E4: 1.5256757 | F4: 1.6398894 | G4: 1.729102 | H4: 46147.478 | I4: 30890.228 | J4: 5.0127698 | K4: 1.5256757 | L4: 1.5811956 | M4: 1.6014891 | N4: 1.622057 | O4: 1.6429019 | P4: 1.6640263 | Q4: 1.6854328 | R4: 1.7071238 | S4: 1.729102
A5: F1b same, bank margin higher @4.50% | B5: 200000 | C5: 2255.5185 | D5: 1.2191479 | E5: 1.2191479 | F5: 1.2974681 | G5: 1.3544824 | H5: 79342.378 | I5: 52596 | J5: 3.0676086 | K5: 1.2191479 | L5: 1.2602228 | M5: 1.2735869 | N5: 1.2869981 | O5: 1.3004489 | P5: 1.3139315 | Q5: 1.3274373 | R5: 1.3409575 | S5: 1.3544824
A6: F1c same @3.25% with 24m grace + 96 | B6: 200000 | C6: 2368.6937 | D6: 5.0112601 | E6: 1.1887171 | F6: 1.6573687 | G6: 1.2886806 | H6: 81342.378 | I6: 40394.593 | J6: 4.170535 | K6: 5.0112601 | L6: 1.1887171 | M6: 1.2025129 | N6: 1.2164696 | O6: 1.2305876 | P6: 1.2448673 | Q6: 1.2593092 | R6: 1.2739136 | S6: 1.2886806
A7: F2 Split: 160k CBJ @3.25% + 40k WC commercial @8.5% / 5y | B7: 200000 | C7: 2531.3479 | D7: 1.0790407 | E7: 1.0790407 | F7: 1.459781 | G7: 1.7830278 | H7: 73162.997 | I7: 39193.835 | J7: 1.825967 | K7: 1.0790407 | L7: 1.113592 | M7: 1.1232215 | N7: 1.1326372 | O7: 1.6933863 | P7: 1.7153487 | Q7: 1.7376079 | R7: 1.7601667 | S7: 1.7830278
A8: F3 Islamic (diminishing musharaka/ijara) unsubsidised @7.0%, 12m grace + 108 | B8: 200000 | C8: 2501.2553 | D8: 1.1317118 | E8: 1.1317118 | F8: 1.189647 | G8: 1.2244719 | H8: 75342.378 | I8: 84135.574 | J8: 2.0434627 | K8: 1.1317118 | L8: 1.1664303 | M8: 1.1758441 | N8: 1.1849539 | O8: 1.1937211 | P8: 1.2021036 | Q8: 1.2100561 | R8: 1.2175298 | S8: 1.2244719
A9: F4 Commercial SME loan + JLGC 70% @9.5% all-in, 72m incl. 12m grace | B9: 200000 | C9: 4200.3723 | D9: 0.69026348 | E9: 0.68842766 | F9: 0.69504482 | H9: -5513.1385 | I9: 71022.336 | J9: 1.5583409 | K9: 0.69026348 | L9: 0.70276167 | M9: 0.69925191 | N9: 0.69451939 | O9: 0.68842766

Sheet Gallery scenarios
A1: Case | B1: Total debt | C1: Monthly payment | D1: DSCR Y2 | E1: Min DSCR Y2-10 | F1: Avg DSCR | G1: DSCR Y10 | H1: Min closing cash | I1: Total interest 10y | J1: DSCR Y1 | K1: DSCR Y2 | L1: DSCR Y3 | M1: DSCR Y4 | N1: DSCR Y5 | O1: DSCR Y6 | P1: DSCR Y7 | Q1: DSCR Y8 | R1: DSCR Y9 | S1: DSCR Y10
A2: G0 No gallery investment (base case) | B2: 165000 | C2: 1764.1456 | D2: 1.5256757 | E2: 1.5256757 | F2: 1.6398894 | G2: 1.729102 | H2: 46147.478 | I2: 30890.228 | J2: 5.0127698 | K2: 1.5256757 | L2: 1.5811956 | M2: 1.6014891 | N2: 1.622057 | O2: 1.6429019 | P2: 1.6640263 | Q2: 1.6854328 | R2: 1.7071238 | S2: 1.729102
A3: G1 Study approach: 100k loan, base revenue 52,434 | B3: 265000 | C3: 2833.3248 | D3: 1.3934122 | E3: 1.3934122 | F3: 1.5992248 | G3: 1.6425372 | H3: 49021.166 | I3: 49611.578 | J3: 3.8321819 | K3: 1.3934122 | L3: 1.5880051 | M3: 1.6070961 | N3: 1.6264203 | O3: 1.6459787 | P3: 1.6657722 | Q3: 1.6017677 | R3: 1.6220338 | S3: 1.6425372
A4: G1c Study approach: 100k loan, conservative 22,500 | B4: 265000 | C4: 2833.3248 | D4: 0.95382749 | E4: 0.95382749 | F4: 1.0339029 | G4: 1.0169322 | H4: 35838.91 | I4: 49611.578 | J4: 2.4838631 | K4: 0.95382749 | L4: 1.0809712 | M4: 1.0501312 | N4: 1.0565738 | O4: 1.0653851 | P4: 1.0742328 | Q4: 0.99908023 | R4: 1.0079924 | S4: 1.0169322
A5: G1s Study approach: 100k loan, ~study price/volume 15,000 stabilized | B5: 265000 | C5: 2833.3248 | D5: 0.77476445 | E5: 0.77476445 | F5: 0.86007426 | G5: 0.82334434 | H5: -9705.8753 | I5: 49611.578 | J5: 1.9848791 | K5: 0.77476445 | L5: 0.87030884 | M5: 0.88346593 | N5: 0.89680359 | O5: 0.91032407 | P5: 0.92402967 | Q5: 0.83942719 | R5: 0.81820029 | S5: 0.82334434
A6: G2 RECOMMENDED Phase 1: 50k tranche, conservative 22,500 | B6: 215000 | C6: 2529.4345 | D6: 1.0790462 | E6: 1.0790462 | F6: 1.3784676 | G6: 1.7727304 | H6: 41574.049 | I6: 37616.029 | J6: 3.4250518 | K6: 1.0790462 | L6: 1.1898523 | M6: 1.2021696 | N6: 1.2146005 | O6: 1.227144 | P6: 1.239799 | Q6: 1.729751 | R6: 1.7511156 | S6: 1.7727304
A7: G2b Phase 1: 50k tranche, base 52,434 | B7: 215000 | C7: 2529.4345 | D7: 1.5842928 | E7: 1.5842928 | F7: 2.1181103 | G7: 2.77749 | H7: 51292.595 | I7: 37616.029 | J7: 4.8158991 | K7: 1.5842928 | L7: 1.8047366 | M7: 1.8286587 | N7: 1.8529093 | O7: 1.877491 | P7: 1.9024069 | Q7: 2.6977036 | R7: 2.7373034 | S7: 2.77749
A8: G3 Phase 1+2: 50k tranche + 50k grant/partner, base 52,434 | B8: 215000 | C8: 2529.4345 | D8: 1.5503119 | E8: 1.5503119 | F8: 2.0459122 | G8: 2.6359072 | H8: 50321.166 | I8: 37616.029 | J8: 4.6768753 | K8: 1.5503119 | L8: 1.7687295 | M8: 1.7905749 | N8: 1.8126967 | O8: 1.8350966 | P8: 1.857776 | Q8: 2.5629431 | R8: 2.5991738 | S8: 2.6359072
A9: G4 High-end 128k: 50k tranche + 78k grant/partner, upside 104,859 | B9: 215000 | C9: 2529.4345 | D9: 2.517719 | E9: 2.517719 | F9: 3.4306623 | G9: 4.493749 | H9: 69805.586 | I9: 37616.029 | J9: 7.4653433 | K9: 2.517719 | L9: 2.9295555 | M9: 2.9731648 | N9: 3.0174627 | O9: 3.0624585 | P9: 3.1081614 | Q9: 4.3515935 | R9: 4.422096 | S9: 4.493749

Sheet Stress tests
A1: Case | B1: Total debt | C1: Monthly payment | D1: DSCR Y2 | E1: Min DSCR Y2-10 | F1: Avg DSCR | G1: DSCR Y10 | H1: Min closing cash | I1: Total interest 10y | J1: DSCR Y1 | K1: DSCR Y2 | L1: DSCR Y3 | M1: DSCR Y4 | N1: DSCR Y5 | O1: DSCR Y6 | P1: DSCR Y7 | Q1: DSCR Y8 | R1: DSCR Y9 | S1: DSCR Y10
A2: Base (recommended F5) | B2: 165000 | C2: 1764.1456 | D2: 1.5256757 | E2: 1.5256757 | F2: 1.6398894 | G2: 1.729102 | H2: 46147.478 | I2: 30890.228 | J2: 5.0127698 | K2: 1.5256757 | L2: 1.5811956 | M2: 1.6014891 | N2: 1.622057 | O2: 1.6429019 | P2: 1.6640263 | Q2: 1.6854328 | R2: 1.7071238 | S2: 1.729102
A3: Occupancy 85% from Y2 | B3: 165000 | C3: 1764.1456 | D3: 1.2907301 | E3: 1.2907301 | F3: 1.3852441 | G3: 1.4538257 | H3: 46147.478 | I3: 30890.228 | J3: 5.0127698 | K3: 1.2907301 | L3: 1.341551 | M3: 1.3570516 | N3: 1.3727308 | O3: 1.3885892 | P3: 1.4046273 | Q3: 1.4208458 | R3: 1.4372451 | S3: 1.4538257
A4: Occupancy 70% from Y2 | B4: 165000 | C4: 1764.1456 | D4: 0.93831154 | E4: 0.93831154 | F4: 1.0032761 | G4: 1.0409112 | H4: 36771.692 | I4: 30890.228 | J4: 3.6215136 | K4: 0.93831154 | L4: 0.98208407 | M4: 0.9903954 | N4: 0.99874145 | O4: 1.00712 | P4: 1.0155288 | Q4: 1.0239653 | R4: 1.032427 | S4: 1.0409112
A5: Revenue -10% | B5: 165000 | C5: 1764.1456 | D5: 1.1928778 | E5: 1.1928778 | F5: 1.2730818 | G5: 1.329404 | H5: 39868.144 | I5: 30890.228 | J5: 3.8417984 | K5: 1.1928778 | L5: 1.2375307 | M5: 1.2503431 | N5: 1.263262 | O5: 1.2762861 | P5: 1.289414 | Q5: 1.302644 | R5: 1.3159746 | S5: 1.329404
A6: Revenue -20% | B6: 165000 | C6: 1764.1456 | D6: 0.86007983 | E6: 0.86007983 | F6: 0.90627424 | G6: 0.92970599 | H6: 15731.455 | I6: 30890.228 | J6: 2.6708271 | K6: 0.86007983 | L6: 0.89386582 | M6: 0.89919706 | N6: 0.90446695 | O6: 0.90967027 | P6: 0.91480159 | Q6: 0.91985525 | R6: 0.92482541 | S6: 0.92970599
A7: Revenue -30% | B7: 165000 | C7: 1764.1456 | D7: 0.50453975 | E7: 0.50453975 | F7: 0.54639851 | G7: 0.56054398 | H7: -60434.892 | I7: 30890.228 | J7: 1.2535701 | K7: 0.50453975 | L7: 0.5394392 | M7: 0.54320862 | N7: 0.54690453 | O7: 0.55052255 | P7: 0.55405813 | Q7: 0.55750662 | R7: 0.5608632 | S7: 0.56054398
A8: OPEX +20% | B8: 165000 | C8: 1764.1456 | D8: 1.140485 | E8: 1.140485 | F8: 1.2138462 | G8: 1.2597845 | H8: 38431.974 | I8: 30890.228 | J8: 3.5739811 | K8: 1.140485 | L8: 1.186375 | M8: 1.1967981 | N8: 1.2072487 | O8: 1.2177234 | P8: 1.2282183 | Q8: 1.2387296 | R8: 1.249253 | S8: 1.2597845
A9: Loss of tower rent | B9: 165000 | C9: 1764.1456 | D9: 1.2499615 | E9: 1.2499615 | F9: 1.3410572 | G9: 1.4060589 | H9: 40925.078 | I9: 30890.228 | J9: 4.0388956 | K9: 1.2499615 | L9: 1.2999671 | M9: 1.3146361 | N9: 1.3294669 | O9: 1.34446 | P9: 1.3596156 | Q9: 1.3749338 | R9: 1.3904149 | S9: 1.4060589
A10: Revenue -30% and OPEX +20% | B10: 165000 | C10: 1764.1456 | D10: 0.023051274 | E10: -0.022524066 | F10: 0.014242155 | G10: -0.022524066 | H10: -171469.81 | I10: 30890.228 | J10: -0.54491567 | K10: 0.023051274 | L10: 0.045913514 | M10: 0.037344786 | N10: 0.028394103 | O10: 0.019049359 | P10: 0.0092981173 | Q10: -0.00087239504 | R10: -0.011475298 | S10: -0.022524066
A11: Tax 21% (company: 20% + 1% national contribution) | B11: 165000 | C11: 1764.1456 | D11: 1.5143329 | E11: 1.5143329 | F11: 1.6257676 | G11: 1.7124076 | H11: 45978.038 | I11: 30890.228 | J11: 4.9811726 | K11: 1.5143329 | L11: 1.5688462 | M11: 1.5885633 | N11: 1.6085406 | O11: 1.6287804 | P11: 1.6492849 | Q11: 1.6700562 | R11: 1.6910964 | S11: 1.7124076
A12: No rent growth | B12: 165000 | C12: 1764.1456 | D12: 1.5256757 | E12: 1.345961 | F12: 1.4527429 | G12: 1.345961 | H12: 46147.478 | I12: 30890.228 | J12: 5.0127698 | K12: 1.5256757 | L12: 1.5365559 | M12: 1.511317 | N12: 1.4854418 | O12: 1.4589147 | P12: 1.4317196 | Q12: 1.4038403 | R12: 1.3752598 | S12: 1.345961
A13: Rate 4.5% (higher bank margin) | B13: 165000 | C13: 1860.8028 | D13: 1.4642396 | E13: 1.4642396 | F13: 1.5650961 | G13: 1.6407806 | H13: 44497.478 | I13: 43391.7 | J13: 3.6758893 | K13: 1.4642396 | L13: 1.5153554 | M13: 1.5329434 | N13: 1.5506523 | O13: 1.568476 | P13: 1.586408 | Q13: 1.6044411 | R13: 1.6225681 | S13: 1.6407806
... A16: Rents -20% (vacancy + discounts) and POS -30% | B16: 165000 | C16: 1764.1456 | D16: 0.76294084 | E16: 0.76294084 | F16: 0.78276423 | G16: 0.79152047 | H16: -10116.068 | I16: 30890.228 | J16: 2.2390432 | K16: 0.76294084 | L16: 0.77786331 | M16: 0.78026664 | N16: 0.78253183 | O16: 0.78465157 | P16: 0.78661828 | Q16: 0.78842413 | R16: 0.79006099 | S16: 0.79152047

Sheet Refinance 140k
A1: Case | B1: Total debt | C1: Monthly payment | D1: DSCR Y2 | E1: Min DSCR Y2-10 | F1: Avg DSCR | G1: DSCR Y10 | H1: Min closing cash | I1: Total interest 10y | J1: DSCR Y1 | K1: DSCR Y2 | L1: DSCR Y3 | M1: DSCR Y4 | N1: DSCR Y5 | O1: DSCR Y6 | P1: DSCR Y7 | Q1: DSCR Y8 | R1: DSCR Y9 | S1: DSCR Y10
A2: R1 250k CBJ sectors programme @3.25%, 12m grace + 108 | B2: 250000 | C2: 2672.9479 | D2: 1.0234078 | E2: 1.0234078 | F2: 1.0914379 | G2: 1.1423894 | H2: 43937.478 | I2: 46803.375 | J2: 3.376428 | K2: 1.0234078 | L2: 1.0583508 | M2: 1.0699882 | N2: 1.0817489 | O2: 1.0936325 | P2: 1.1056387 | Q2: 1.1177673 | R2: 1.1300177 | S2: 1.1423894
A3: R2 305k (140k refi + 165k new) CBJ @3.25%, 12m grace + 108 | B3: 305000 | C3: 3260.9965 | D3: 0.84758986 | E3: 0.84758986 | F3: 0.89945347 | G3: 0.93701175 | H3: 7096.2346 | I3: 57100.118 | J3: 2.8036295 | K3: 0.84758986 | L3: 0.87532986 | M3: 0.88393731 | N3: 0.89261498 | O3: 0.90136168 | P3: 0.91017613 | Q3: 0.91905696 | R3: 0.92800269 | S3: 0.93701175
A4: R3 110k CBJ @3.25% + 140k refi commercial @8.5% 10y | B4: 250000 | C4: 3035.2065 | D4: 0.94044834 | E4: 0.94044834 | F4: 0.98504285 | G4: 1.0097868 | H4: 32595.779 | I4: 93277.298 | J4: 1.867753 | K4: 0.94044834 | L4: 0.96843294 | M4: 0.97551062 | N4: 0.98227535 | O4: 0.98868503 | P4: 0.99469366 | Q4: 1.000251 | R4: 1.005302 | S4: 1.0097868
A5: R4 110k CBJ @3.25% + 140k refi Islamic @7% 15y (12m grace + 168) | B5: 250000 | C5: 2485.6578 | D5: 1.1357761 | E5: 1.1357761 | F5: 1.2078781 | G5: 1.2601573 | H5: 39737.478 | I5: 97961.476 | J5: 2.1296058 | K5: 1.1357761 | L5: 1.1734024 | M5: 1.1858526 | N5: 1.1983084 | O5: 1.2107562 | P5: 1.2231815 | Q5: 1.2355685 | R5: 1.2479 | S5: 1.2601573
A6: R5 RECOMMENDED if 250k: one 250k Islamic diminishing musharaka/ijara @7% 15y (12m grace + 168) | B6: 250000 | C6: 2338.5014 | D6: 1.2366924 | E6: 1.2366924 | F6: 1.3124513 | G6: 1.3659229 | H6: 36437.478 | I6: 138157.13 | J6: 1.6747702 | K6: 1.2366924 | L6: 1.2767287 | M6: 1.2899087 | N6: 1.3029887 | O6: 1.3159432 | P6: 1.328745 | Q6: 1.3413641 | R6: 1.3537684 | S6: 1.3659229
A7: R5s R5 with revenue -10% | B7: 250000 | C7: 2338.5014 | D7: 1.007318 | E7: 1.007318 | F7: 1.0381443 | G7: 1.0643941 | H7: 29549.604 | I7: 138157.13 | J7: 1.2811774 | K7: 1.007318 | L7: 1.0174708 | M7: 1.0250071 | N7: 1.0323167 | O7: 1.0393714 | P7: 1.0461406 | Q7: 1.0525915 | R7: 1.0586887 | S7: 1.0643941
A8: R6 250k commercial @8.5% 15y (12m grace + 168) | B8: 250000 | C8: 2549.7963 | D8: 1.1585438 | E8: 1.1585438 | F8: 1.2247546 | G8: 1.2688056 | H8: 33437.478 | I8: 170908.09 | J8: 1.4145166 | K8: 1.1585438 | L8: 1.1948003 | M8: 1.2063023 | N8: 1.2175717 | O8: 1.2285664 | P8: 1.2392403 | Q8: 1.2495427 | R8: 1.2594181 | S8: 1.2688056
A9: R7 305k: 165k CBJ + 140k refi Islamic @7% 15y | B9: 305000 | C9: 3073.7064 | D9: 0.9277472 | E9: 0.9277472 | F9: 0.98191864 | G9: 1.0197345 | H9: 31089.089 | I9: 108258.22 | J9: 1.9021255 | K9: 0.9277472 | L9: 0.95721834 | M9: 0.96629837 | N9: 0.97535029 | O9: 0.98436214 | P9: 0.99332102 | Q9: 1.002213 | R9: 1.0110229 | S9: 1.0197345
A10: Cap: 205k CBJ @3.25% 10y (DSCR ~1.25 limit) | B10: 205000 | C10: 2191.8173 | D10: 1.2374302 | E10: 1.2374302 | F10: 1.3251396 | G10: 1.3923947 | H10: 45107.478 | I10: 38378.768 | J10: 4.0736927 | K10: 1.2374302 | L10: 1.2811412 | M10: 1.2964671 | N10: 1.3119806 | O10: 1.3276827 | P10: 1.3435743 | Q10: 1.3596563 | R10: 1.3759295 | S10: 1.3923947
